{
 "cells": [
  {
   "cell_type": "markdown",
   "metadata": {
    "pycharm": {
     "name": "#%% md\n"
    }
   },
   "source": [
    "# TI Calculation\n"
   ]
  },
  {
   "cell_type": "markdown",
   "metadata": {},
   "source": [
    "## Imports"
   ]
  },
  {
   "cell_type": "code",
   "execution_count": 1,
   "metadata": {
    "pycharm": {
     "name": "#%%\n"
    }
   },
   "outputs": [],
   "source": [
    "#for analysis\n",
    "from matplotlib import pyplot as plt\n",
    "%matplotlib inline\n",
    "\n",
    "import os\n",
    "import numpy as np\n",
    "import pygromos\n",
    "from pygromos.files.gromos_system import Gromos_System\n",
    "from pygromos.simulations.hpc_queuing.submission_systems.local import LOCAL as subSystem\n",
    "from pygromos.files.blocks.imd_blocks import PERTURBATION, WRITETRAJ\n",
    "\n",
    "from pygromos.utils import bash"
   ]
  },
  {
   "cell_type": "markdown",
   "metadata": {
    "pycharm": {
     "name": "#%% md\n"
    }
   },
   "source": [
    "## Input files"
   ]
  },
  {
   "cell_type": "code",
   "execution_count": 2,
   "metadata": {
    "pycharm": {
     "name": "#%%\n"
    }
   },
   "outputs": [],
   "source": [
    "root_dir = os.path.abspath(os.path.dirname(pygromos.__file__)+\"/../examples/example_files/TI_Calculation\")\n",
    "root_in_dir = root_dir+\"/TI_input\"\n",
    "cnf_path = root_in_dir+\"/M030_6KET.cnf\"\n",
    "top_path = root_in_dir + \"/M030_6KET.top\"\n",
    "disres_path = root_in_dir+\"/M030_6KET.disres\"\n",
    "\n",
    "\n",
    "sys_name = \"M030_to_6KET\"\n",
    "lam = 0\n",
    "\n",
    "project_dir = bash.make_folder(root_dir+\"/\"+sys_name)\n",
    "input_dir = bash.make_folder(project_dir+\"/input\")"
   ]
  },
  {
   "cell_type": "markdown",
   "metadata": {
    "pycharm": {
     "name": "#%% md\n"
    }
   },
   "source": [
    "## Vacuum Simulation\n",
    "\n",
    "### Direction A->B\n",
    "\n",
    "#### Setup:\n",
    "\n",
    "\n",
    "##### Build pertubation file\n"
   ]
  },
  {
   "cell_type": "code",
   "execution_count": 3,
   "metadata": {
    "pycharm": {
     "name": "#%%\n"
    }
   },
   "outputs": [
    {
     "name": "stdout",
     "output_type": "stream",
     "text": [
      "\n",
      "\n",
      "==================\n",
      "\tCHECK dependencies\n",
      "\n",
      "Check /home/bschroed/Documents/projects/PyGromosTools/examples/example_files/TI_Calculation/M030_to_6KET/input\n",
      "Check /home/bschroed/Documents/projects/PyGromosTools/examples/example_files/TI_Calculation/TI_input/M030_6KET.top\n",
      "Check /home/bschroed/Documents/projects/PyGromosTools/examples/example_files/TI_Calculation/TI_input/M030_6KET.cnf\n",
      "Check /home/bschroed/Documents/projects/PyGromosTools/examples/example_files/TI_Calculation/TI_input/M030_6KET.disres\n",
      "/home/bschroed/Documents/projects/PyGromosTools/examples/example_files/TI_Calculation/M030_to_6KET/input\n",
      "/home/bschroed/Documents/projects/PyGromosTools/examples/example_files/TI_Calculation/TI_input/M030_6KET.top\n",
      "/home/bschroed/Documents/projects/PyGromosTools/examples/example_files/TI_Calculation/TI_input/M030_6KET.cnf\n",
      "/home/bschroed/Documents/projects/PyGromosTools/examples/example_files/TI_Calculation/TI_input/M030_6KET.disres\n",
      "All dependencies are correct! \n",
      "\n",
      "\n",
      "Generate Empty:  imd\n",
      "Parsing File:  top\n",
      "Parsing File:  cnf\n",
      "Parsing File:  disres\n"
     ]
    },
    {
     "name": "stderr",
     "output_type": "stream",
     "text": [
      "/home/bschroed/Documents/projects/PyGromosTools/pygromos/files/gromos_system/gromos_system.py:131: UserWarning: No data provided to gromos_system\n",
      "manual work needed\n",
      "  if verbose: warnings.warn(\"No data provided to gromos_system\\nmanual work needed\")\n"
     ]
    },
    {
     "data": {
      "text/plain": [
       "TITLE\n",
       "Automatic generated pertubation file. \n",
       "\t >>> Generated with python lib function_libs utilities. (riniker group)\n",
       "\t >>> line_seperator: '\\n'\t field_seperator: '\\t'\t comments_char: '#'\n",
       "END\n",
       "PERTATOMPARAM\n",
       "# NJLA  \t NPTB =  \t 2 \t \n",
       " \t 26\n",
       "# state_identifiers\n",
       "#  \t state1 \t state2\n",
       "#    NR   RES  NAME  IAC1mass1   CHARGE1  IAC2mass2   CHARGE2    ALPHLJ     ALPHCRF   \n",
       "    1     1    C9    16 15.035    0.05200    22 15.035    0.00000    1.00000    1.00000\n",
       "    2     1    C6    64 12.011    0.21300    22 12.011    0.00000    1.00000    1.00000\n",
       "    3     1    C2    64 12.011   -0.43400    22 12.011    0.00000    1.00000    1.00000\n",
       "    4     1    H2    20 1.008    0.16900    22 1.008    0.00000    1.00000    1.00000\n",
       "    5     1    C4    64 12.011    0.21300    22 12.011    0.00000    1.00000    1.00000\n",
       "    6     1    C7    16 15.035    0.05200    22 15.035    0.00000    1.00000    1.00000\n",
       "    7     1    C1    64 12.011   -0.43400    22 12.011    0.00000    1.00000    1.00000\n",
       "    8     1    H1    20 1.008    0.16900    22 1.008    0.00000    1.00000    1.00000\n",
       "    9     1    C5    64 12.011    0.21300    22 12.011    0.00000    1.00000    1.00000\n",
       "   10     1    C3    64 12.011   -0.43400    22 12.011    0.00000    1.00000    1.00000\n",
       "   11     1    H3    20 1.008    0.16900    22 1.008    0.00000    1.00000    1.00000\n",
       "   12     1    C8    16 15.035    0.05200    22 15.035    0.00000    1.00000    1.00000\n",
       "   13     2    H8    22 1.008    0.00000    59 1.008    0.45800    1.00000    1.00000\n",
       "   14     2    O1    22 15.9994    0.00000    68 15.9994   -0.62000    1.00000    1.00000\n",
       "   15     2    C5    22 12.011    0.00000    64 12.011    0.48400    1.00000    1.00000\n",
       "   16     2    C2    22 12.011    0.00000    64 12.011   -0.35300    1.00000    1.00000\n",
       "   17     2    H2    22 1.008    0.00000    20 1.008    0.18400    1.00000    1.00000\n",
       "   18     2    C1    22 12.011    0.00000    64 12.011   -0.10700    1.00000    1.00000\n",
       "   19     2    H1    22 1.008    0.00000    20 1.008    0.15200    1.00000    1.00000\n",
       "   20     2    C3    22 12.011    0.00000    64 12.011   -0.29800    1.00000    1.00000\n",
       "   21     2    H3    22 1.008    0.00000    20 1.008    0.14200    1.00000    1.00000\n",
       "   22     2    C6    22 12.011    0.00000    64 12.011    0.40300    1.00000    1.00000\n",
       "   23     2    C4    22 12.011    0.00000    64 12.011   -0.53100    1.00000    1.00000\n",
       "   24     2    H4    22 1.008    0.00000    20 1.008    0.19400    1.00000    1.00000\n",
       "   25     2    O2    22 15.9994    0.00000     4 15.9994   -0.38700    1.00000    1.00000\n",
       "   26     2    C7    22 15.035    0.00000    16 15.035    0.27900    1.00000    1.00000\n",
       "END"
      ]
     },
     "execution_count": 3,
     "metadata": {},
     "output_type": "execute_result"
    }
   ],
   "source": [
    "from pygromos.files.topology.ptp import Pertubation_topology\n",
    "from pygromos.files.blocks.topology_blocks import pertubation_lam_state, atom_lam_pertubation_state, PERTATOMPARAM, TITLE\n",
    "\n",
    "\n",
    "#External imd_changes:\n",
    "grom_system = Gromos_System(in_cnf_path=cnf_path, in_top_path=top_path,\n",
    "                            in_disres_path=disres_path,\n",
    "                            system_name=sys_name, work_folder=input_dir)\n",
    "\n",
    "\n",
    "#Build up lambda - States\n",
    "pert_atoms=[]\n",
    "for atom_line in grom_system.top.SOLUTEATOM:\n",
    "    states = {}\n",
    "    phys_state = pertubation_lam_state(IAC=atom_line.IAC, MASS=atom_line.MASS, CHARGE=atom_line.CG)\n",
    "    states = {atom_line.MRES: phys_state }\n",
    "\n",
    "    pert_atom = atom_lam_pertubation_state(atom_line.ATNM,RES=atom_line.MRES,NAME=atom_line.PANM, STATES=states)\n",
    "    pert_atoms.append(pert_atom)\n",
    "pert_atom_block = PERTATOMPARAM(pert_atoms)\n",
    "\n",
    "# Generate ptp file\n",
    "grom_system.ptp = Pertubation_topology(in_value = None)\n",
    "grom_system.ptp.PERTATOMPARAM = pert_atom_block\n",
    "grom_system.ptp.TITLE = TITLE(\"Automatic generated pertubation file. \")\n",
    "\n",
    "grom_system.ptp"
   ]
  },
  {
   "cell_type": "code",
   "execution_count": 4,
   "metadata": {
    "pycharm": {
     "name": "#%%\n"
    }
   },
   "outputs": [
    {
     "name": "stdout",
     "output_type": "stream",
     "text": [
      "File imd is empty , can not be written!\n"
     ]
    },
    {
     "name": "stderr",
     "output_type": "stream",
     "text": [
      "/home/bschroed/Documents/projects/PyGromosTools/pygromos/files/gromos_system/gromos_system.py:552: UserWarning: Did not change file path as its only promised None\n",
      "  if(self.verbose or True): warnings.warn(\"Did not change file path as its only promised \" + str(file_obj.path))\n",
      "/home/bschroed/Documents/projects/PyGromosTools/pygromos/files/gromos_system/gromos_system.py:802: UserWarning: FOUND ALREADY A FILE! SKIPPING!\n",
      "  warnings.warn(\"FOUND ALREADY A FILE! SKIPPING!\")\n"
     ]
    },
    {
     "data": {
      "text/plain": [
       "\n",
       "GROMOS SYSTEM: M030_to_6KET\n",
       "################################################################################\n",
       "WORKDIR: /home/bschroed/Documents/projects/PyGromosTools/examples/example_files/TI_Calculation/M030_to_6KET/input\n",
       "LAST CHECKPOINT: None\n",
       "\n",
       "GromosXX_bin: None\n",
       "GromosPP_bin: None\n",
       "FILES: \n",
       "\timd: None\n",
       "\ttop: /home/bschroed/Documents/projects/PyGromosTools/examples/example_files/TI_Calculation/M030_to_6KET/input/M030_to_6KET.top\n",
       "\tcnf: /home/bschroed/Documents/projects/PyGromosTools/examples/example_files/TI_Calculation/M030_to_6KET/input/M030_to_6KET.cnf\n",
       "\tdisres: /home/bschroed/Documents/projects/PyGromosTools/examples/example_files/TI_Calculation/M030_to_6KET/input/M030_to_6KET.disres\n",
       "\tptp: /home/bschroed/Documents/projects/PyGromosTools/examples/example_files/TI_Calculation/M030_to_6KET/input/M030_to_6KET.ptp\n",
       "FUTURE PROMISE: False\n",
       "SYSTEM: \n",
       "\tSolute:\t['M030', '6KET']  resID: [1, 2]  natoms: 26\n",
       "\tSOLVENT:\t[]  nmolecules: 0  natoms: 0\n",
       "\n"
      ]
     },
     "execution_count": 4,
     "metadata": {},
     "output_type": "execute_result"
    }
   ],
   "source": [
    "##Write out all generated files\n",
    "grom_system.rebase_files()\n",
    "\n",
    "##save Input System\n",
    "grom_system.save(root_dir+\"/initial_startSys.obj\")\n",
    "grom_system"
   ]
  },
  {
   "cell_type": "markdown",
   "metadata": {},
   "source": [
    "### RUN Emin"
   ]
  },
  {
   "cell_type": "code",
   "execution_count": 5,
   "metadata": {
    "pycharm": {
     "name": "#%%\n"
    }
   },
   "outputs": [
    {
     "name": "stdout",
     "output_type": "stream",
     "text": [
      "/home/bschroed/Documents/projects/PyGromosTools/pygromos\n",
      "/home/bschroed/Documents/projects/PyGromosTools/pygromos\n",
      "/home/bschroed/Documents/projects/PyGromosTools/pygromos\n"
     ]
    }
   ],
   "source": [
    "# PREPARE EMIN\n",
    "## IMPORT\n",
    "from pygromos.data.simulation_parameters_templates import template_emin_vac\n",
    "from pygromos.simulations.modules.preset_simulation_modules import emin\n",
    "\n",
    "grom_system = Gromos_System.load(root_dir+\"/initial_startSys.obj\")\n",
    "step_name  = \"a_emin\" #also the dir_name, out prefix etc.\n",
    "grom_system.imd = template_emin_vac #read template imd\n",
    "\n",
    "#Pertubation for molecules to sim params\n",
    "pert_block  =  PERTURBATION(NTG=1, NRDGL=0, RLAM=lam, DLAMT=0,\n",
    "                            ALPHC=0.5, ALPHLJ=0.5, NLAM=2, NSCALE=0)\n",
    "grom_system.imd.add_block(block=pert_block)\n",
    "\n",
    "#save checkpoint system\n",
    "step_dir = project_dir+\"/\"+step_name\n"
   ]
  },
  {
   "cell_type": "code",
   "execution_count": 6,
   "metadata": {
    "pycharm": {
     "name": "#%%\n"
    }
   },
   "outputs": [
    {
     "name": "stdout",
     "output_type": "stream",
     "text": [
      "\n",
      "\n",
      "==================\n",
      "\tCHECK dependencies\n",
      "\n",
      "Check /home/bschroed/Documents/projects/PyGromosTools/examples/example_files/TI_Calculation/M030_to_6KET/input\n",
      "/home/bschroed/Documents/projects/PyGromosTools/examples/example_files/TI_Calculation/M030_to_6KET/input\n",
      "All dependencies are correct! \n",
      "\n",
      "\n",
      "Generate Empty:  imd\n",
      "Generate Empty:  top\n",
      "Generate Empty:  cnf\n",
      "################################################################################\n",
      "\n",
      "a_emin\n",
      "################################################################################\n",
      "\n",
      "Script:  /home/bschroed/Documents/projects/PyGromosTools/pygromos/simulations/hpc_queuing/job_scheduling/schedulers/simulation_scheduler.py\n",
      "################################################################################\n",
      "Simulation PREPERATION\n",
      "################################################################################\n",
      "\n",
      "\n",
      "\n",
      "################################################################################\n",
      "Simulation Setup:\n",
      "################################################################################\n",
      "\n",
      "steps_per_run:  3000\n",
      "equis:  0\n",
      "simulation runs:  1\n",
      "################################################################################\n",
      "\n",
      " submit Final AnaLysis part \n",
      "\n",
      "/home/bschroed/Documents/projects/PyGromosTools/examples/example_files/TI_Calculation/M030_to_6KET/a_emin/ana_out.log\n",
      "/home/bschroed/Documents/projects/PyGromosTools/examples/example_files/TI_Calculation/M030_to_6KET/a_emin/job_analysis.py\n",
      "ANA jobID: 0\n"
     ]
    },
    {
     "data": {
      "text/plain": [
       "\n",
       "GROMOS SYSTEM: a_emin\n",
       "################################################################################\n",
       "WORKDIR: /home/bschroed/Documents/projects/PyGromosTools/examples/example_files/TI_Calculation/M030_to_6KET/a_emin\n",
       "LAST CHECKPOINT: /home/bschroed/Documents/projects/PyGromosTools/examples/example_files/TI_Calculation/M030_to_6KET/a_emin/emin_out.obj\n",
       "\n",
       "GromosXX_bin: None\n",
       "GromosPP_bin: None\n",
       "FILES: \n",
       "\timd: /home/bschroed/Documents/projects/PyGromosTools/examples/example_files/TI_Calculation/M030_to_6KET/a_emin/a_emin.imd\n",
       "\ttop: /home/bschroed/Documents/projects/PyGromosTools/examples/example_files/TI_Calculation/M030_to_6KET/a_emin/a_emin.top\n",
       "\tcnf: /home/bschroed/Documents/projects/PyGromosTools/examples/example_files/TI_Calculation/M030_to_6KET/a_emin/a_emin.cnf\n",
       "\tdisres: /home/bschroed/Documents/projects/PyGromosTools/examples/example_files/TI_Calculation/M030_to_6KET/a_emin/a_emin.disres\n",
       "\tptp: /home/bschroed/Documents/projects/PyGromosTools/examples/example_files/TI_Calculation/M030_to_6KET/a_emin/a_emin.ptp\n",
       "FUTURE PROMISE: True\n",
       "SYSTEM: \n",
       "\tSolute:\t['M030', '6KET']  resID: [1, 2]  natoms: 26\n",
       "\tSOLVENT:\t[]  nmolecules: 0  natoms: 0\n",
       "\n"
      ]
     },
     "execution_count": 6,
     "metadata": {},
     "output_type": "execute_result"
    }
   ],
   "source": [
    "#EXECUTE EMIN\n",
    "emin_gromos_system, jobID = emin(in_gromos_system=grom_system, project_dir=project_dir,\n",
    "                          step_name=step_name, submission_system=subSystem())\n",
    "\n",
    "emin_gromos_system.save(step_dir+\"/emin_out.obj\")\n",
    "emin_gromos_system"
   ]
  },
  {
   "cell_type": "markdown",
   "metadata": {},
   "source": [
    "## RUN Test SD EQ"
   ]
  },
  {
   "cell_type": "code",
   "execution_count": 7,
   "metadata": {
    "pycharm": {
     "name": "#%%\n"
    }
   },
   "outputs": [],
   "source": [
    "from pygromos.data.simulation_parameters_templates import template_sd\n",
    "from pygromos.simulations.modules.preset_simulation_modules import sd\n",
    "\n",
    "grom_system = Gromos_System.load(root_dir+\"/M030_to_6KET/a_emin/emin_out.obj\")\n",
    "step_name  = \"b_vacuum_sd\"\n",
    "grom_system.imd = template_sd\n",
    "\n",
    "#Pertubation\n",
    "pert_block  =  PERTURBATION(NTG=1, NRDGL=0, RLAM=lam, DLAMT=0,\n",
    "                            ALPHC=0.5, ALPHLJ=0.5, NLAM=2, NSCALE=0)\n",
    "grom_system.imd.add_block(block=pert_block)\n",
    "\n",
    "#write out trajs:\n",
    "write_traj = WRITETRAJ(NTWX=100, NTWE=100)\n",
    "grom_system.imd.add_block(block=write_traj)\n",
    "step_dir = project_dir+\"/\"+step_name\n",
    "\n",
    "#further mods:\n",
    "grom_system.imd.CONSTRAINT.NTC = 3\n",
    "grom_system.imd.FORCE.BONDS = 0\n",
    "\n",
    "grom_system.imd.COVALENTFORM.NTBAH = 0\n",
    "grom_system.imd.COVALENTFORM.NTBDN = 0\n",
    "grom_system.imd.COVALENTFORM.NTBBH = 0\n",
    "\n",
    "grom_system.imd.STEP.NSTLIM = 30000\n",
    "\n",
    "\n"
   ]
  },
  {
   "cell_type": "code",
   "execution_count": null,
   "metadata": {
    "pycharm": {
     "name": "#%%\n"
    }
   },
   "outputs": [
    {
     "name": "stdout",
     "output_type": "stream",
     "text": [
      "\n",
      "\n",
      "==================\n",
      "\tCHECK dependencies\n",
      "\n",
      "Check /home/bschroed/Documents/projects/PyGromosTools/examples/example_files/TI_Calculation/M030_to_6KET/a_emin\n",
      "/home/bschroed/Documents/projects/PyGromosTools/examples/example_files/TI_Calculation/M030_to_6KET/a_emin\n",
      "All dependencies are correct! \n",
      "\n",
      "\n",
      "Generate Empty:  imd\n",
      "Generate Empty:  top\n",
      "Generate Empty:  cnf\n",
      "################################################################################\n",
      "\n",
      "b_vacuum_sd\n",
      "################################################################################\n",
      "\n",
      "Script:  /home/bschroed/Documents/projects/PyGromosTools/pygromos/simulations/hpc_queuing/job_scheduling/schedulers/simulation_scheduler.py\n",
      "################################################################################\n",
      "Simulation PREPERATION\n",
      "################################################################################\n",
      "\n",
      "\n",
      "\n",
      "################################################################################\n",
      "Simulation Setup:\n",
      "################################################################################\n",
      "\n",
      "steps_per_run:  30000\n",
      "equis:  1\n",
      "simulation runs:  1\n",
      "################################################################################\n",
      "\n",
      " submit Final AnaLysis part \n",
      "\n",
      "/home/bschroed/Documents/projects/PyGromosTools/examples/example_files/TI_Calculation/M030_to_6KET/b_vacuum_sd/ana_out.log\n",
      "/home/bschroed/Documents/projects/PyGromosTools/examples/example_files/TI_Calculation/M030_to_6KET/b_vacuum_sd/job_analysis.py\n",
      "ANA jobID: 0\n"
     ]
    },
    {
     "name": "stderr",
     "output_type": "stream",
     "text": [
      "ERROR:root:Internal Python error in the inspect module.\n",
      "Below is the traceback from this internal error.\n",
      "\n",
      "ERROR:root:Internal Python error in the inspect module.\n",
      "Below is the traceback from this internal error.\n",
      "\n",
      "ERROR:root:Internal Python error in the inspect module.\n",
      "Below is the traceback from this internal error.\n",
      "\n"
     ]
    },
    {
     "name": "stdout",
     "output_type": "stream",
     "text": [
      "Traceback (most recent call last):\n",
      "  File \"/home/bschroed/anaconda3/envs/pyGromosTools/lib/python3.7/pkgutil.py\", line 415, in get_importer\n",
      "    importer = sys.path_importer_cache[path_item]\n",
      "KeyError: ''\n",
      "\n",
      "During handling of the above exception, another exception occurred:\n",
      "\n",
      "Traceback (most recent call last):\n",
      "  File \"/home/bschroed/anaconda3/envs/pyGromosTools/lib/python3.7/site-packages/IPython/core/interactiveshell.py\", line 3441, in run_code\n",
      "    exec(code_obj, self.user_global_ns, self.user_ns)\n",
      "  File \"<ipython-input-8-5bbdbc5d1c43>\", line 3, in <module>\n",
      "    equilibration_runs=1, simulation_runs=1)\n",
      "  File \"/home/bschroed/Documents/projects/PyGromosTools/pygromos/simulations/modules/preset_simulation_modules.py\", line 43, in sd\n",
      "    analysis_script=analysis_script, _template_imd_path=_template_imd_path)\n",
      "  File \"/home/bschroed/Documents/projects/PyGromosTools/pygromos/simulations/modules/general_simulation_modules.py\", line 188, in simulation\n",
      "    in_gromos_system.trc = Trc(input_value=final_trc_file+\".h5\")\n",
      "  File \"/home/bschroed/Documents/projects/PyGromosTools/pygromos/files/trajectory/trc.py\", line 32, in __init__\n",
      "    super().__init__(input_value, auto_save=auto_save, stride=stride, skip=skip)\n",
      "  File \"/home/bschroed/Documents/projects/PyGromosTools/pygromos/files/trajectory/_general_trajectory.py\", line 48, in __init__\n",
      "    self._read_from_file(input_path=input_value, auto_save=auto_save, stride=stride, skip=skip)\n",
      "  File \"/home/bschroed/Documents/projects/PyGromosTools/pygromos/files/trajectory/_general_trajectory.py\", line 136, in _read_from_file\n",
      "    self._read_db_from_hf5(input_path=input_path)\n",
      "  File \"/home/bschroed/Documents/projects/PyGromosTools/pygromos/files/trajectory/_general_trajectory.py\", line 144, in _read_db_from_hf5\n",
      "    self.database = pandas.read_hdf(path_or_buf=input_path, key=input_path.split(\".\")[-1])\n",
      "  File \"/home/bschroed/anaconda3/envs/pyGromosTools/lib/python3.7/site-packages/pandas/io/pytables.py\", line 399, in read_hdf\n",
      "    store = HDFStore(path_or_buf, mode=mode, errors=errors, **kwargs)\n",
      "  File \"/home/bschroed/anaconda3/envs/pyGromosTools/lib/python3.7/site-packages/pandas/io/pytables.py\", line 542, in __init__\n",
      "    tables = import_optional_dependency(\"tables\")\n",
      "  File \"/home/bschroed/anaconda3/envs/pyGromosTools/lib/python3.7/site-packages/pandas/compat/_optional.py\", line 106, in import_optional_dependency\n",
      "    module = importlib.import_module(name)\n",
      "  File \"/home/bschroed/anaconda3/envs/pyGromosTools/lib/python3.7/importlib/__init__.py\", line 127, in import_module\n",
      "    return _bootstrap._gcd_import(name[level:], package, level)\n",
      "  File \"<frozen importlib._bootstrap>\", line 1006, in _gcd_import\n",
      "  File \"<frozen importlib._bootstrap>\", line 983, in _find_and_load\n",
      "  File \"<frozen importlib._bootstrap>\", line 967, in _find_and_load_unlocked\n",
      "  File \"<frozen importlib._bootstrap>\", line 677, in _load_unlocked\n",
      "  File \"<frozen importlib._bootstrap_external>\", line 728, in exec_module\n",
      "  File \"<frozen importlib._bootstrap>\", line 219, in _call_with_frames_removed\n",
      "  File \"/home/bschroed/anaconda3/envs/pyGromosTools/lib/python3.7/site-packages/tables/__init__.py\", line 148, in <module>\n",
      "    from .tests import print_versions, test\n",
      "  File \"/home/bschroed/anaconda3/envs/pyGromosTools/lib/python3.7/site-packages/tables/tests/__init__.py\", line 21, in <module>\n",
      "    from tables.tests.common import print_versions\n",
      "  File \"/home/bschroed/anaconda3/envs/pyGromosTools/lib/python3.7/site-packages/tables/tests/common.py\", line 25, in <module>\n",
      "    from pkg_resources import resource_filename\n",
      "  File \"/home/bschroed/anaconda3/envs/pyGromosTools/lib/python3.7/site-packages/pkg_resources/__init__.py\", line 3242, in <module>\n",
      "    @_call_aside\n",
      "  File \"/home/bschroed/anaconda3/envs/pyGromosTools/lib/python3.7/site-packages/pkg_resources/__init__.py\", line 3226, in _call_aside\n",
      "    f(*args, **kwargs)\n",
      "  File \"/home/bschroed/anaconda3/envs/pyGromosTools/lib/python3.7/site-packages/pkg_resources/__init__.py\", line 3255, in _initialize_master_working_set\n",
      "    working_set = WorkingSet._build_master()\n",
      "  File \"/home/bschroed/anaconda3/envs/pyGromosTools/lib/python3.7/site-packages/pkg_resources/__init__.py\", line 559, in _build_master\n",
      "    ws = cls()\n",
      "  File \"/home/bschroed/anaconda3/envs/pyGromosTools/lib/python3.7/site-packages/pkg_resources/__init__.py\", line 552, in __init__\n",
      "    self.add_entry(entry)\n",
      "  File \"/home/bschroed/anaconda3/envs/pyGromosTools/lib/python3.7/site-packages/pkg_resources/__init__.py\", line 608, in add_entry\n",
      "    for dist in find_distributions(entry, True):\n",
      "  File \"/home/bschroed/anaconda3/envs/pyGromosTools/lib/python3.7/site-packages/pkg_resources/__init__.py\", line 1964, in find_distributions\n",
      "    importer = get_importer(path_item)\n",
      "  File \"/home/bschroed/anaconda3/envs/pyGromosTools/lib/python3.7/pkgutil.py\", line 419, in get_importer\n",
      "    importer = path_hook(path_item)\n",
      "  File \"<frozen importlib._bootstrap_external>\", line 1447, in path_hook_for_FileFinder\n",
      "  File \"<frozen importlib._bootstrap_external>\", line 101, in _path_isdir\n",
      "FileNotFoundError: [Errno 2] No such file or directory\n",
      "\n",
      "During handling of the above exception, another exception occurred:\n",
      "\n",
      "Traceback (most recent call last):\n",
      "  File \"/home/bschroed/anaconda3/envs/pyGromosTools/lib/python3.7/site-packages/IPython/core/interactiveshell.py\", line 2061, in showtraceback\n",
      "    stb = value._render_traceback_()\n",
      "AttributeError: 'FileNotFoundError' object has no attribute '_render_traceback_'\n",
      "\n",
      "During handling of the above exception, another exception occurred:\n",
      "\n",
      "Traceback (most recent call last):\n",
      "  File \"/home/bschroed/anaconda3/envs/pyGromosTools/lib/python3.7/site-packages/IPython/core/ultratb.py\", line 1101, in get_records\n",
      "    return _fixed_getinnerframes(etb, number_of_lines_of_context, tb_offset)\n",
      "  File \"/home/bschroed/anaconda3/envs/pyGromosTools/lib/python3.7/site-packages/IPython/core/ultratb.py\", line 248, in wrapped\n",
      "    return f(*args, **kwargs)\n",
      "  File \"/home/bschroed/anaconda3/envs/pyGromosTools/lib/python3.7/site-packages/IPython/core/ultratb.py\", line 281, in _fixed_getinnerframes\n",
      "    records = fix_frame_records_filenames(inspect.getinnerframes(etb, context))\n",
      "  File \"/home/bschroed/anaconda3/envs/pyGromosTools/lib/python3.7/inspect.py\", line 1502, in getinnerframes\n",
      "    frameinfo = (tb.tb_frame,) + getframeinfo(tb, context)\n",
      "  File \"/home/bschroed/anaconda3/envs/pyGromosTools/lib/python3.7/inspect.py\", line 1460, in getframeinfo\n",
      "    filename = getsourcefile(frame) or getfile(frame)\n",
      "  File \"/home/bschroed/anaconda3/envs/pyGromosTools/lib/python3.7/inspect.py\", line 696, in getsourcefile\n",
      "    if getattr(getmodule(object, filename), '__loader__', None) is not None:\n",
      "  File \"/home/bschroed/anaconda3/envs/pyGromosTools/lib/python3.7/inspect.py\", line 725, in getmodule\n",
      "    file = getabsfile(object, _filename)\n",
      "  File \"/home/bschroed/anaconda3/envs/pyGromosTools/lib/python3.7/inspect.py\", line 709, in getabsfile\n",
      "    return os.path.normcase(os.path.abspath(_filename))\n",
      "  File \"/home/bschroed/anaconda3/envs/pyGromosTools/lib/python3.7/posixpath.py\", line 383, in abspath\n",
      "    cwd = os.getcwd()\n",
      "FileNotFoundError: [Errno 2] No such file or directory\n",
      "Traceback (most recent call last):\n",
      "  File \"/home/bschroed/anaconda3/envs/pyGromosTools/lib/python3.7/pkgutil.py\", line 415, in get_importer\n",
      "    importer = sys.path_importer_cache[path_item]\n",
      "KeyError: ''\n",
      "\n",
      "During handling of the above exception, another exception occurred:\n",
      "\n",
      "Traceback (most recent call last):\n",
      "  File \"/home/bschroed/anaconda3/envs/pyGromosTools/lib/python3.7/site-packages/IPython/core/interactiveshell.py\", line 3441, in run_code\n",
      "    exec(code_obj, self.user_global_ns, self.user_ns)\n",
      "  File \"<ipython-input-8-5bbdbc5d1c43>\", line 3, in <module>\n",
      "    equilibration_runs=1, simulation_runs=1)\n",
      "  File \"/home/bschroed/Documents/projects/PyGromosTools/pygromos/simulations/modules/preset_simulation_modules.py\", line 43, in sd\n",
      "    analysis_script=analysis_script, _template_imd_path=_template_imd_path)\n",
      "  File \"/home/bschroed/Documents/projects/PyGromosTools/pygromos/simulations/modules/general_simulation_modules.py\", line 188, in simulation\n",
      "    in_gromos_system.trc = Trc(input_value=final_trc_file+\".h5\")\n",
      "  File \"/home/bschroed/Documents/projects/PyGromosTools/pygromos/files/trajectory/trc.py\", line 32, in __init__\n",
      "    super().__init__(input_value, auto_save=auto_save, stride=stride, skip=skip)\n",
      "  File \"/home/bschroed/Documents/projects/PyGromosTools/pygromos/files/trajectory/_general_trajectory.py\", line 48, in __init__\n",
      "    self._read_from_file(input_path=input_value, auto_save=auto_save, stride=stride, skip=skip)\n",
      "  File \"/home/bschroed/Documents/projects/PyGromosTools/pygromos/files/trajectory/_general_trajectory.py\", line 136, in _read_from_file\n",
      "    self._read_db_from_hf5(input_path=input_path)\n",
      "  File \"/home/bschroed/Documents/projects/PyGromosTools/pygromos/files/trajectory/_general_trajectory.py\", line 144, in _read_db_from_hf5\n",
      "    self.database = pandas.read_hdf(path_or_buf=input_path, key=input_path.split(\".\")[-1])\n",
      "  File \"/home/bschroed/anaconda3/envs/pyGromosTools/lib/python3.7/site-packages/pandas/io/pytables.py\", line 399, in read_hdf\n",
      "    store = HDFStore(path_or_buf, mode=mode, errors=errors, **kwargs)\n",
      "  File \"/home/bschroed/anaconda3/envs/pyGromosTools/lib/python3.7/site-packages/pandas/io/pytables.py\", line 542, in __init__\n",
      "    tables = import_optional_dependency(\"tables\")\n",
      "  File \"/home/bschroed/anaconda3/envs/pyGromosTools/lib/python3.7/site-packages/pandas/compat/_optional.py\", line 106, in import_optional_dependency\n",
      "    module = importlib.import_module(name)\n",
      "  File \"/home/bschroed/anaconda3/envs/pyGromosTools/lib/python3.7/importlib/__init__.py\", line 127, in import_module\n",
      "    return _bootstrap._gcd_import(name[level:], package, level)\n",
      "  File \"<frozen importlib._bootstrap>\", line 1006, in _gcd_import\n",
      "  File \"<frozen importlib._bootstrap>\", line 983, in _find_and_load\n",
      "  File \"<frozen importlib._bootstrap>\", line 967, in _find_and_load_unlocked\n",
      "  File \"<frozen importlib._bootstrap>\", line 677, in _load_unlocked\n",
      "  File \"<frozen importlib._bootstrap_external>\", line 728, in exec_module\n",
      "  File \"<frozen importlib._bootstrap>\", line 219, in _call_with_frames_removed\n",
      "  File \"/home/bschroed/anaconda3/envs/pyGromosTools/lib/python3.7/site-packages/tables/__init__.py\", line 148, in <module>\n",
      "    from .tests import print_versions, test\n",
      "  File \"/home/bschroed/anaconda3/envs/pyGromosTools/lib/python3.7/site-packages/tables/tests/__init__.py\", line 21, in <module>\n",
      "    from tables.tests.common import print_versions\n",
      "  File \"/home/bschroed/anaconda3/envs/pyGromosTools/lib/python3.7/site-packages/tables/tests/common.py\", line 25, in <module>\n",
      "    from pkg_resources import resource_filename\n",
      "  File \"/home/bschroed/anaconda3/envs/pyGromosTools/lib/python3.7/site-packages/pkg_resources/__init__.py\", line 3242, in <module>\n",
      "    @_call_aside\n",
      "  File \"/home/bschroed/anaconda3/envs/pyGromosTools/lib/python3.7/site-packages/pkg_resources/__init__.py\", line 3226, in _call_aside\n",
      "    f(*args, **kwargs)\n",
      "  File \"/home/bschroed/anaconda3/envs/pyGromosTools/lib/python3.7/site-packages/pkg_resources/__init__.py\", line 3255, in _initialize_master_working_set\n",
      "    working_set = WorkingSet._build_master()\n",
      "  File \"/home/bschroed/anaconda3/envs/pyGromosTools/lib/python3.7/site-packages/pkg_resources/__init__.py\", line 559, in _build_master\n",
      "    ws = cls()\n",
      "  File \"/home/bschroed/anaconda3/envs/pyGromosTools/lib/python3.7/site-packages/pkg_resources/__init__.py\", line 552, in __init__\n",
      "    self.add_entry(entry)\n",
      "  File \"/home/bschroed/anaconda3/envs/pyGromosTools/lib/python3.7/site-packages/pkg_resources/__init__.py\", line 608, in add_entry\n",
      "    for dist in find_distributions(entry, True):\n",
      "  File \"/home/bschroed/anaconda3/envs/pyGromosTools/lib/python3.7/site-packages/pkg_resources/__init__.py\", line 1964, in find_distributions\n",
      "    importer = get_importer(path_item)\n",
      "  File \"/home/bschroed/anaconda3/envs/pyGromosTools/lib/python3.7/pkgutil.py\", line 419, in get_importer\n",
      "    importer = path_hook(path_item)\n",
      "  File \"<frozen importlib._bootstrap_external>\", line 1447, in path_hook_for_FileFinder\n",
      "  File \"<frozen importlib._bootstrap_external>\", line 101, in _path_isdir\n",
      "FileNotFoundError: [Errno 2] No such file or directory\n",
      "\n",
      "During handling of the above exception, another exception occurred:\n",
      "\n",
      "Traceback (most recent call last):\n",
      "  File \"/home/bschroed/anaconda3/envs/pyGromosTools/lib/python3.7/site-packages/IPython/core/interactiveshell.py\", line 2061, in showtraceback\n",
      "    stb = value._render_traceback_()\n",
      "AttributeError: 'FileNotFoundError' object has no attribute '_render_traceback_'\n",
      "\n",
      "During handling of the above exception, another exception occurred:\n",
      "\n",
      "Traceback (most recent call last):\n",
      "  File \"/home/bschroed/anaconda3/envs/pyGromosTools/lib/python3.7/site-packages/IPython/core/interactiveshell.py\", line 3361, in run_ast_nodes\n",
      "    if (await self.run_code(code, result,  async_=asy)):\n",
      "  File \"/home/bschroed/anaconda3/envs/pyGromosTools/lib/python3.7/site-packages/IPython/core/interactiveshell.py\", line 3458, in run_code\n",
      "    self.showtraceback(running_compiled_code=True)\n",
      "  File \"/home/bschroed/anaconda3/envs/pyGromosTools/lib/python3.7/site-packages/IPython/core/interactiveshell.py\", line 2064, in showtraceback\n",
      "    value, tb, tb_offset=tb_offset)\n",
      "  File \"/home/bschroed/anaconda3/envs/pyGromosTools/lib/python3.7/site-packages/IPython/core/ultratb.py\", line 1368, in structured_traceback\n",
      "    self, etype, value, tb, tb_offset, number_of_lines_of_context)\n",
      "  File \"/home/bschroed/anaconda3/envs/pyGromosTools/lib/python3.7/site-packages/IPython/core/ultratb.py\", line 1268, in structured_traceback\n",
      "    self, etype, value, tb, tb_offset, number_of_lines_of_context\n",
      "  File \"/home/bschroed/anaconda3/envs/pyGromosTools/lib/python3.7/site-packages/IPython/core/ultratb.py\", line 1125, in structured_traceback\n",
      "    tb_offset)\n",
      "  File \"/home/bschroed/anaconda3/envs/pyGromosTools/lib/python3.7/site-packages/IPython/core/ultratb.py\", line 1082, in format_exception_as_a_whole\n",
      "    last_unique, recursion_repeat = find_recursion(orig_etype, evalue, records)\n",
      "  File \"/home/bschroed/anaconda3/envs/pyGromosTools/lib/python3.7/site-packages/IPython/core/ultratb.py\", line 382, in find_recursion\n",
      "    return len(records), 0\n",
      "TypeError: object of type 'NoneType' has no len()\n",
      "\n",
      "During handling of the above exception, another exception occurred:\n",
      "\n",
      "Traceback (most recent call last):\n",
      "  File \"/home/bschroed/anaconda3/envs/pyGromosTools/lib/python3.7/site-packages/IPython/core/interactiveshell.py\", line 2061, in showtraceback\n",
      "    stb = value._render_traceback_()\n",
      "AttributeError: 'TypeError' object has no attribute '_render_traceback_'\n",
      "\n",
      "During handling of the above exception, another exception occurred:\n",
      "\n",
      "Traceback (most recent call last):\n",
      "  File \"/home/bschroed/anaconda3/envs/pyGromosTools/lib/python3.7/site-packages/IPython/core/ultratb.py\", line 1101, in get_records\n",
      "    return _fixed_getinnerframes(etb, number_of_lines_of_context, tb_offset)\n",
      "  File \"/home/bschroed/anaconda3/envs/pyGromosTools/lib/python3.7/site-packages/IPython/core/ultratb.py\", line 248, in wrapped\n",
      "    return f(*args, **kwargs)\n",
      "  File \"/home/bschroed/anaconda3/envs/pyGromosTools/lib/python3.7/site-packages/IPython/core/ultratb.py\", line 281, in _fixed_getinnerframes\n",
      "    records = fix_frame_records_filenames(inspect.getinnerframes(etb, context))\n",
      "  File \"/home/bschroed/anaconda3/envs/pyGromosTools/lib/python3.7/inspect.py\", line 1502, in getinnerframes\n",
      "    frameinfo = (tb.tb_frame,) + getframeinfo(tb, context)\n",
      "  File \"/home/bschroed/anaconda3/envs/pyGromosTools/lib/python3.7/inspect.py\", line 1460, in getframeinfo\n",
      "    filename = getsourcefile(frame) or getfile(frame)\n",
      "  File \"/home/bschroed/anaconda3/envs/pyGromosTools/lib/python3.7/inspect.py\", line 696, in getsourcefile\n",
      "    if getattr(getmodule(object, filename), '__loader__', None) is not None:\n",
      "  File \"/home/bschroed/anaconda3/envs/pyGromosTools/lib/python3.7/inspect.py\", line 725, in getmodule\n",
      "    file = getabsfile(object, _filename)\n",
      "  File \"/home/bschroed/anaconda3/envs/pyGromosTools/lib/python3.7/inspect.py\", line 709, in getabsfile\n",
      "    return os.path.normcase(os.path.abspath(_filename))\n",
      "  File \"/home/bschroed/anaconda3/envs/pyGromosTools/lib/python3.7/posixpath.py\", line 383, in abspath\n",
      "    cwd = os.getcwd()\n",
      "FileNotFoundError: [Errno 2] No such file or directory\n",
      "Traceback (most recent call last):\n",
      "  File \"/home/bschroed/anaconda3/envs/pyGromosTools/lib/python3.7/pkgutil.py\", line 415, in get_importer\n",
      "    importer = sys.path_importer_cache[path_item]\n",
      "KeyError: ''\n",
      "\n",
      "During handling of the above exception, another exception occurred:\n",
      "\n",
      "Traceback (most recent call last):\n",
      "  File \"/home/bschroed/anaconda3/envs/pyGromosTools/lib/python3.7/site-packages/IPython/core/interactiveshell.py\", line 3441, in run_code\n",
      "    exec(code_obj, self.user_global_ns, self.user_ns)\n",
      "  File \"<ipython-input-8-5bbdbc5d1c43>\", line 3, in <module>\n",
      "    equilibration_runs=1, simulation_runs=1)\n",
      "  File \"/home/bschroed/Documents/projects/PyGromosTools/pygromos/simulations/modules/preset_simulation_modules.py\", line 43, in sd\n",
      "    analysis_script=analysis_script, _template_imd_path=_template_imd_path)\n",
      "  File \"/home/bschroed/Documents/projects/PyGromosTools/pygromos/simulations/modules/general_simulation_modules.py\", line 188, in simulation\n",
      "    in_gromos_system.trc = Trc(input_value=final_trc_file+\".h5\")\n",
      "  File \"/home/bschroed/Documents/projects/PyGromosTools/pygromos/files/trajectory/trc.py\", line 32, in __init__\n",
      "    super().__init__(input_value, auto_save=auto_save, stride=stride, skip=skip)\n",
      "  File \"/home/bschroed/Documents/projects/PyGromosTools/pygromos/files/trajectory/_general_trajectory.py\", line 48, in __init__\n",
      "    self._read_from_file(input_path=input_value, auto_save=auto_save, stride=stride, skip=skip)\n",
      "  File \"/home/bschroed/Documents/projects/PyGromosTools/pygromos/files/trajectory/_general_trajectory.py\", line 136, in _read_from_file\n",
      "    self._read_db_from_hf5(input_path=input_path)\n",
      "  File \"/home/bschroed/Documents/projects/PyGromosTools/pygromos/files/trajectory/_general_trajectory.py\", line 144, in _read_db_from_hf5\n",
      "    self.database = pandas.read_hdf(path_or_buf=input_path, key=input_path.split(\".\")[-1])\n",
      "  File \"/home/bschroed/anaconda3/envs/pyGromosTools/lib/python3.7/site-packages/pandas/io/pytables.py\", line 399, in read_hdf\n",
      "    store = HDFStore(path_or_buf, mode=mode, errors=errors, **kwargs)\n",
      "  File \"/home/bschroed/anaconda3/envs/pyGromosTools/lib/python3.7/site-packages/pandas/io/pytables.py\", line 542, in __init__\n",
      "    tables = import_optional_dependency(\"tables\")\n",
      "  File \"/home/bschroed/anaconda3/envs/pyGromosTools/lib/python3.7/site-packages/pandas/compat/_optional.py\", line 106, in import_optional_dependency\n",
      "    module = importlib.import_module(name)\n",
      "  File \"/home/bschroed/anaconda3/envs/pyGromosTools/lib/python3.7/importlib/__init__.py\", line 127, in import_module\n",
      "    return _bootstrap._gcd_import(name[level:], package, level)\n",
      "  File \"<frozen importlib._bootstrap>\", line 1006, in _gcd_import\n",
      "  File \"<frozen importlib._bootstrap>\", line 983, in _find_and_load\n",
      "  File \"<frozen importlib._bootstrap>\", line 967, in _find_and_load_unlocked\n",
      "  File \"<frozen importlib._bootstrap>\", line 677, in _load_unlocked\n",
      "  File \"<frozen importlib._bootstrap_external>\", line 728, in exec_module\n",
      "  File \"<frozen importlib._bootstrap>\", line 219, in _call_with_frames_removed\n",
      "  File \"/home/bschroed/anaconda3/envs/pyGromosTools/lib/python3.7/site-packages/tables/__init__.py\", line 148, in <module>\n",
      "    from .tests import print_versions, test\n",
      "  File \"/home/bschroed/anaconda3/envs/pyGromosTools/lib/python3.7/site-packages/tables/tests/__init__.py\", line 21, in <module>\n",
      "    from tables.tests.common import print_versions\n",
      "  File \"/home/bschroed/anaconda3/envs/pyGromosTools/lib/python3.7/site-packages/tables/tests/common.py\", line 25, in <module>\n",
      "    from pkg_resources import resource_filename\n",
      "  File \"/home/bschroed/anaconda3/envs/pyGromosTools/lib/python3.7/site-packages/pkg_resources/__init__.py\", line 3242, in <module>\n",
      "    @_call_aside\n",
      "  File \"/home/bschroed/anaconda3/envs/pyGromosTools/lib/python3.7/site-packages/pkg_resources/__init__.py\", line 3226, in _call_aside\n",
      "    f(*args, **kwargs)\n",
      "  File \"/home/bschroed/anaconda3/envs/pyGromosTools/lib/python3.7/site-packages/pkg_resources/__init__.py\", line 3255, in _initialize_master_working_set\n",
      "    working_set = WorkingSet._build_master()\n",
      "  File \"/home/bschroed/anaconda3/envs/pyGromosTools/lib/python3.7/site-packages/pkg_resources/__init__.py\", line 559, in _build_master\n",
      "    ws = cls()\n",
      "  File \"/home/bschroed/anaconda3/envs/pyGromosTools/lib/python3.7/site-packages/pkg_resources/__init__.py\", line 552, in __init__\n",
      "    self.add_entry(entry)\n",
      "  File \"/home/bschroed/anaconda3/envs/pyGromosTools/lib/python3.7/site-packages/pkg_resources/__init__.py\", line 608, in add_entry\n",
      "    for dist in find_distributions(entry, True):\n",
      "  File \"/home/bschroed/anaconda3/envs/pyGromosTools/lib/python3.7/site-packages/pkg_resources/__init__.py\", line 1964, in find_distributions\n",
      "    importer = get_importer(path_item)\n",
      "  File \"/home/bschroed/anaconda3/envs/pyGromosTools/lib/python3.7/pkgutil.py\", line 419, in get_importer\n",
      "    importer = path_hook(path_item)\n",
      "  File \"<frozen importlib._bootstrap_external>\", line 1447, in path_hook_for_FileFinder\n",
      "  File \"<frozen importlib._bootstrap_external>\", line 101, in _path_isdir\n",
      "FileNotFoundError: [Errno 2] No such file or directory\n",
      "\n",
      "During handling of the above exception, another exception occurred:\n",
      "\n",
      "Traceback (most recent call last):\n",
      "  File \"/home/bschroed/anaconda3/envs/pyGromosTools/lib/python3.7/site-packages/IPython/core/interactiveshell.py\", line 2061, in showtraceback\n",
      "    stb = value._render_traceback_()\n",
      "AttributeError: 'FileNotFoundError' object has no attribute '_render_traceback_'\n",
      "\n",
      "During handling of the above exception, another exception occurred:\n",
      "\n",
      "Traceback (most recent call last):\n",
      "  File \"/home/bschroed/anaconda3/envs/pyGromosTools/lib/python3.7/site-packages/IPython/core/interactiveshell.py\", line 3361, in run_ast_nodes\n",
      "    if (await self.run_code(code, result,  async_=asy)):\n",
      "  File \"/home/bschroed/anaconda3/envs/pyGromosTools/lib/python3.7/site-packages/IPython/core/interactiveshell.py\", line 3458, in run_code\n",
      "    self.showtraceback(running_compiled_code=True)\n",
      "  File \"/home/bschroed/anaconda3/envs/pyGromosTools/lib/python3.7/site-packages/IPython/core/interactiveshell.py\", line 2064, in showtraceback\n",
      "    value, tb, tb_offset=tb_offset)\n",
      "  File \"/home/bschroed/anaconda3/envs/pyGromosTools/lib/python3.7/site-packages/IPython/core/ultratb.py\", line 1368, in structured_traceback\n",
      "    self, etype, value, tb, tb_offset, number_of_lines_of_context)\n",
      "  File \"/home/bschroed/anaconda3/envs/pyGromosTools/lib/python3.7/site-packages/IPython/core/ultratb.py\", line 1268, in structured_traceback\n",
      "    self, etype, value, tb, tb_offset, number_of_lines_of_context\n",
      "  File \"/home/bschroed/anaconda3/envs/pyGromosTools/lib/python3.7/site-packages/IPython/core/ultratb.py\", line 1125, in structured_traceback\n",
      "    tb_offset)\n",
      "  File \"/home/bschroed/anaconda3/envs/pyGromosTools/lib/python3.7/site-packages/IPython/core/ultratb.py\", line 1082, in format_exception_as_a_whole\n",
      "    last_unique, recursion_repeat = find_recursion(orig_etype, evalue, records)\n",
      "  File \"/home/bschroed/anaconda3/envs/pyGromosTools/lib/python3.7/site-packages/IPython/core/ultratb.py\", line 382, in find_recursion\n",
      "    return len(records), 0\n",
      "TypeError: object of type 'NoneType' has no len()\n",
      "\n",
      "During handling of the above exception, another exception occurred:\n",
      "\n",
      "Traceback (most recent call last):\n",
      "  File \"/home/bschroed/anaconda3/envs/pyGromosTools/lib/python3.7/site-packages/IPython/core/interactiveshell.py\", line 2061, in showtraceback\n",
      "    stb = value._render_traceback_()\n",
      "AttributeError: 'TypeError' object has no attribute '_render_traceback_'\n",
      "\n",
      "During handling of the above exception, another exception occurred:\n",
      "\n",
      "Traceback (most recent call last):\n",
      "  File \"/home/bschroed/anaconda3/envs/pyGromosTools/lib/python3.7/site-packages/IPython/core/interactiveshell.py\", line 2944, in _run_cell\n",
      "    return runner(coro)\n",
      "  File \"/home/bschroed/anaconda3/envs/pyGromosTools/lib/python3.7/site-packages/IPython/core/async_helpers.py\", line 68, in _pseudo_sync_runner\n",
      "    coro.send(None)\n",
      "  File \"/home/bschroed/anaconda3/envs/pyGromosTools/lib/python3.7/site-packages/IPython/core/interactiveshell.py\", line 3170, in run_cell_async\n",
      "    interactivity=interactivity, compiler=compiler, result=result)\n",
      "  File \"/home/bschroed/anaconda3/envs/pyGromosTools/lib/python3.7/site-packages/IPython/core/interactiveshell.py\", line 3380, in run_ast_nodes\n",
      "    self.showtraceback()\n",
      "  File \"/home/bschroed/anaconda3/envs/pyGromosTools/lib/python3.7/site-packages/IPython/core/interactiveshell.py\", line 2064, in showtraceback\n",
      "    value, tb, tb_offset=tb_offset)\n",
      "  File \"/home/bschroed/anaconda3/envs/pyGromosTools/lib/python3.7/site-packages/IPython/core/ultratb.py\", line 1368, in structured_traceback\n",
      "    self, etype, value, tb, tb_offset, number_of_lines_of_context)\n",
      "  File \"/home/bschroed/anaconda3/envs/pyGromosTools/lib/python3.7/site-packages/IPython/core/ultratb.py\", line 1268, in structured_traceback\n",
      "    self, etype, value, tb, tb_offset, number_of_lines_of_context\n",
      "  File \"/home/bschroed/anaconda3/envs/pyGromosTools/lib/python3.7/site-packages/IPython/core/ultratb.py\", line 1143, in structured_traceback\n",
      "    chained_exceptions_tb_offset)\n",
      "  File \"/home/bschroed/anaconda3/envs/pyGromosTools/lib/python3.7/site-packages/IPython/core/ultratb.py\", line 1082, in format_exception_as_a_whole\n",
      "    last_unique, recursion_repeat = find_recursion(orig_etype, evalue, records)\n",
      "  File \"/home/bschroed/anaconda3/envs/pyGromosTools/lib/python3.7/site-packages/IPython/core/ultratb.py\", line 382, in find_recursion\n",
      "    return len(records), 0\n",
      "TypeError: object of type 'NoneType' has no len()\n",
      "\n",
      "During handling of the above exception, another exception occurred:\n",
      "\n",
      "Traceback (most recent call last):\n",
      "  File \"/home/bschroed/anaconda3/envs/pyGromosTools/lib/python3.7/site-packages/IPython/core/interactiveshell.py\", line 2061, in showtraceback\n",
      "    stb = value._render_traceback_()\n",
      "AttributeError: 'TypeError' object has no attribute '_render_traceback_'\n",
      "\n",
      "During handling of the above exception, another exception occurred:\n",
      "\n",
      "Traceback (most recent call last):\n",
      "  File \"/home/bschroed/anaconda3/envs/pyGromosTools/lib/python3.7/site-packages/IPython/core/ultratb.py\", line 1101, in get_records\n",
      "    return _fixed_getinnerframes(etb, number_of_lines_of_context, tb_offset)\n",
      "  File \"/home/bschroed/anaconda3/envs/pyGromosTools/lib/python3.7/site-packages/IPython/core/ultratb.py\", line 248, in wrapped\n",
      "    return f(*args, **kwargs)\n",
      "  File \"/home/bschroed/anaconda3/envs/pyGromosTools/lib/python3.7/site-packages/IPython/core/ultratb.py\", line 281, in _fixed_getinnerframes\n",
      "    records = fix_frame_records_filenames(inspect.getinnerframes(etb, context))\n",
      "  File \"/home/bschroed/anaconda3/envs/pyGromosTools/lib/python3.7/inspect.py\", line 1502, in getinnerframes\n",
      "    frameinfo = (tb.tb_frame,) + getframeinfo(tb, context)\n",
      "  File \"/home/bschroed/anaconda3/envs/pyGromosTools/lib/python3.7/inspect.py\", line 1460, in getframeinfo\n",
      "    filename = getsourcefile(frame) or getfile(frame)\n",
      "  File \"/home/bschroed/anaconda3/envs/pyGromosTools/lib/python3.7/inspect.py\", line 696, in getsourcefile\n",
      "    if getattr(getmodule(object, filename), '__loader__', None) is not None:\n",
      "  File \"/home/bschroed/anaconda3/envs/pyGromosTools/lib/python3.7/inspect.py\", line 725, in getmodule\n",
      "    file = getabsfile(object, _filename)\n",
      "  File \"/home/bschroed/anaconda3/envs/pyGromosTools/lib/python3.7/inspect.py\", line 709, in getabsfile\n",
      "    return os.path.normcase(os.path.abspath(_filename))\n",
      "  File \"/home/bschroed/anaconda3/envs/pyGromosTools/lib/python3.7/posixpath.py\", line 383, in abspath\n",
      "    cwd = os.getcwd()\n",
      "FileNotFoundError: [Errno 2] No such file or directory\n"
     ]
    }
   ],
   "source": [
    "sd_gromos_system, jobID  = sd(in_gromos_system=grom_system, project_dir=project_dir,\n",
    "                              step_name=step_name, submission_system=subSystem(), in_imd_path=None,\n",
    "                      equilibration_runs=1, simulation_runs=1)\n",
    "sd_gromos_system.save(step_dir+\"/sd_out_system.obj\")\n",
    "sd_gromos_system"
   ]
  },
  {
   "cell_type": "markdown",
   "metadata": {
    "pycharm": {
     "name": "#%% md\n"
    }
   },
   "source": [
    "## Further Analysis:\n",
    "Transform the trc into a pdb traj to check it out with pymol :!)"
   ]
  },
  {
   "cell_type": "code",
   "execution_count": 12,
   "metadata": {
    "pycharm": {
     "name": "#%%\n"
    }
   },
   "outputs": [
    {
     "name": "stdout",
     "output_type": "stream",
     "text": [
      "ERROR! Session/line number was not unique in database. History logging moved to new session 175\n"
     ]
    }
   ],
   "source": [
    "#final analysis dir:\n",
    "from pygromos.utils import bash\n",
    "\n",
    "out_ana = project_dir+\"/c_ana\"\n",
    "if(not os.path.exists(out_ana)):\n",
    "    bash.make_folder(out_ana)"
   ]
  },
  {
   "cell_type": "code",
   "execution_count": 13,
   "metadata": {},
   "outputs": [
    {
     "data": {
      "text/plain": [
       "'/home/bschroed/Documents/projects/PyGromosTools/examples/example_files/TI_Calculation/M030_to_6KET'"
      ]
     },
     "execution_count": 13,
     "metadata": {},
     "output_type": "execute_result"
    }
   ],
   "source": [
    "project_dir"
   ]
  },
  {
   "cell_type": "code",
   "execution_count": 14,
   "metadata": {
    "pycharm": {
     "name": "#%%\n"
    }
   },
   "outputs": [
    {
     "data": {
      "text/plain": [
       "'/home/bschroed/Documents/projects/PyGromosTools/examples/example_files/TI_Calculation/M030_to_6KET/a_emin/analysis/data/a_emin.pdb'"
      ]
     },
     "execution_count": 14,
     "metadata": {},
     "output_type": "execute_result"
    }
   ],
   "source": [
    "from pygromos.files.coord import Cnf\n",
    "in_path=project_dir+\"/a_emin/analysis/data/a_emin.cnf\"\n",
    "cnf_file = Cnf(in_path)\n",
    "cnf_file.write_pdb(in_path.replace(\"cnf\", \"pdb\"))\n"
   ]
  },
  {
   "cell_type": "code",
   "execution_count": 11,
   "metadata": {},
   "outputs": [
    {
     "data": {
      "application/3dmoljs_load.v0": "<div id=\"3dmolviewer_16359488111560726\"  style=\"position: relative; width: 400px; height: 400px\">\n        <p id=\"3dmolwarning_16359488111560726\" style=\"background-color:#ffcccc;color:black\">You appear to be running in JupyterLab (or JavaScript failed to load for some other reason).  You need to install the 3dmol extension: <br>\n        <tt>jupyter labextension install jupyterlab_3dmol</tt></p>\n        </div>\n<script>\n\nvar loadScriptAsync = function(uri){\n  return new Promise((resolve, reject) => {\n    var tag = document.createElement('script');\n    tag.src = uri;\n    tag.async = true;\n    tag.onload = () => {\n      resolve();\n    };\n  var firstScriptTag = document.getElementsByTagName('script')[0];\n  firstScriptTag.parentNode.insertBefore(tag, firstScriptTag);\n});\n};\n\nif(typeof $3Dmolpromise === 'undefined') {\n$3Dmolpromise = null;\n  $3Dmolpromise = loadScriptAsync('https://3dmol.org/build/3Dmol.js');\n}\n\nvar viewer_16359488111560726 = null;\nvar warn = document.getElementById(\"3dmolwarning_16359488111560726\");\nif(warn) {\n    warn.parentNode.removeChild(warn);\n}\n$3Dmolpromise.then(function() {\nviewer_16359488111560726 = $3Dmol.createViewer($(\"#3dmolviewer_16359488111560726\"),{backgroundColor:\"white\"});\nviewer_16359488111560726.zoomTo();\n\tviewer_16359488111560726.addModel(\"26\\n# \\tMD++# exported wit PyGromosTools\\nC  \\t-2.859959910    0.433631680    0.007559000\\nC  \\t-1.370531700    0.130355830    0.002212640\\nC  \\t-0.923656880   -1.185836140   -0.004914030\\nH  \\t-1.646042420   -2.002002080   -0.006662890\\nC  \\t 0.437023590   -1.469509160   -0.009828060\\nC  \\t 0.919016070   -2.911043990   -0.017613540\\nC  \\t 1.353575230   -0.424337520   -0.007565720\\nH  \\t 2.421751800   -0.641868350   -0.011400120\\nC  \\t 0.918854630    0.896016500   -0.000452770\\nC  \\t-0.444551110    1.167011580    0.004411390\\nH  \\t-0.790284960    2.200825000    0.009995020\\nC  \\t 1.926221850    2.034263110    0.001986470\\nH  \\t-2.872220440    1.385081560    0.010492500\\nO  \\t-2.712860860    0.426366590   -0.003060180\\nC  \\t-1.373879500    0.188795690   -0.021126830\\nC  \\t-0.949770990   -1.145251010    0.000434240\\nH  \\t-1.682864420   -1.951115970   -0.035001770\\nC  \\t 0.408725880   -1.437206570   -0.039670830\\nH  \\t 0.742163900   -2.475012740   -0.031852810\\nC  \\t 1.347562910   -0.400359690    0.020691670\\nH  \\t 2.412640200   -0.631422560   -0.001702290\\nC  \\t 0.922051110    0.933163460   -0.004915550\\nC  \\t-0.447056300    1.223299570    0.035128330\\nH  \\t-0.785316570    2.259467560    0.029136370\\nO  \\t 1.734472530    2.023045630    0.038120280\\nC  \\t 3.144898240    1.786903560    0.036019830\\n\");\n\tviewer_16359488111560726.setStyle({\"model\": -1},{\"stick\": {}});\n\tviewer_16359488111560726.zoomTo();\nviewer_16359488111560726.render();\n});\n</script>",
      "text/html": [
       "<div id=\"3dmolviewer_16359488111560726\"  style=\"position: relative; width: 400px; height: 400px\">\n",
       "        <p id=\"3dmolwarning_16359488111560726\" style=\"background-color:#ffcccc;color:black\">You appear to be running in JupyterLab (or JavaScript failed to load for some other reason).  You need to install the 3dmol extension: <br>\n",
       "        <tt>jupyter labextension install jupyterlab_3dmol</tt></p>\n",
       "        </div>\n",
       "<script>\n",
       "\n",
       "var loadScriptAsync = function(uri){\n",
       "  return new Promise((resolve, reject) => {\n",
       "    var tag = document.createElement('script');\n",
       "    tag.src = uri;\n",
       "    tag.async = true;\n",
       "    tag.onload = () => {\n",
       "      resolve();\n",
       "    };\n",
       "  var firstScriptTag = document.getElementsByTagName('script')[0];\n",
       "  firstScriptTag.parentNode.insertBefore(tag, firstScriptTag);\n",
       "});\n",
       "};\n",
       "\n",
       "if(typeof $3Dmolpromise === 'undefined') {\n",
       "$3Dmolpromise = null;\n",
       "  $3Dmolpromise = loadScriptAsync('https://3dmol.org/build/3Dmol.js');\n",
       "}\n",
       "\n",
       "var viewer_16359488111560726 = null;\n",
       "var warn = document.getElementById(\"3dmolwarning_16359488111560726\");\n",
       "if(warn) {\n",
       "    warn.parentNode.removeChild(warn);\n",
       "}\n",
       "$3Dmolpromise.then(function() {\n",
       "viewer_16359488111560726 = $3Dmol.createViewer($(\"#3dmolviewer_16359488111560726\"),{backgroundColor:\"white\"});\n",
       "viewer_16359488111560726.zoomTo();\n",
       "\tviewer_16359488111560726.addModel(\"26\\n# \\tMD++# exported wit PyGromosTools\\nC  \\t-2.859959910    0.433631680    0.007559000\\nC  \\t-1.370531700    0.130355830    0.002212640\\nC  \\t-0.923656880   -1.185836140   -0.004914030\\nH  \\t-1.646042420   -2.002002080   -0.006662890\\nC  \\t 0.437023590   -1.469509160   -0.009828060\\nC  \\t 0.919016070   -2.911043990   -0.017613540\\nC  \\t 1.353575230   -0.424337520   -0.007565720\\nH  \\t 2.421751800   -0.641868350   -0.011400120\\nC  \\t 0.918854630    0.896016500   -0.000452770\\nC  \\t-0.444551110    1.167011580    0.004411390\\nH  \\t-0.790284960    2.200825000    0.009995020\\nC  \\t 1.926221850    2.034263110    0.001986470\\nH  \\t-2.872220440    1.385081560    0.010492500\\nO  \\t-2.712860860    0.426366590   -0.003060180\\nC  \\t-1.373879500    0.188795690   -0.021126830\\nC  \\t-0.949770990   -1.145251010    0.000434240\\nH  \\t-1.682864420   -1.951115970   -0.035001770\\nC  \\t 0.408725880   -1.437206570   -0.039670830\\nH  \\t 0.742163900   -2.475012740   -0.031852810\\nC  \\t 1.347562910   -0.400359690    0.020691670\\nH  \\t 2.412640200   -0.631422560   -0.001702290\\nC  \\t 0.922051110    0.933163460   -0.004915550\\nC  \\t-0.447056300    1.223299570    0.035128330\\nH  \\t-0.785316570    2.259467560    0.029136370\\nO  \\t 1.734472530    2.023045630    0.038120280\\nC  \\t 3.144898240    1.786903560    0.036019830\\n\");\n",
       "\tviewer_16359488111560726.setStyle({\"model\": -1},{\"stick\": {}});\n",
       "\tviewer_16359488111560726.zoomTo();\n",
       "viewer_16359488111560726.render();\n",
       "});\n",
       "</script>"
      ]
     },
     "metadata": {},
     "output_type": "display_data"
    },
    {
     "data": {
      "text/plain": [
       "<py3Dmol.view at 0x7f8f88298850>"
      ]
     },
     "execution_count": 11,
     "metadata": {},
     "output_type": "execute_result"
    }
   ],
   "source": [
    "cnf_file.visualize()"
   ]
  },
  {
   "cell_type": "code",
   "execution_count": null,
   "metadata": {
    "pycharm": {
     "name": "#%%\n"
    }
   },
   "outputs": [
    {
     "name": "stderr",
     "output_type": "stream",
     "text": [
      "ERROR:root:Internal Python error in the inspect module.\n",
      "Below is the traceback from this internal error.\n",
      "\n",
      "ERROR:root:Internal Python error in the inspect module.\n",
      "Below is the traceback from this internal error.\n",
      "\n",
      "ERROR:root:Internal Python error in the inspect module.\n",
      "Below is the traceback from this internal error.\n",
      "\n"
     ]
    },
    {
     "name": "stdout",
     "output_type": "stream",
     "text": [
      "Traceback (most recent call last):\n",
      "  File \"/home/bschroed/anaconda3/envs/pyGromosTools/lib/python3.7/pkgutil.py\", line 415, in get_importer\n",
      "    importer = sys.path_importer_cache[path_item]\n",
      "KeyError: ''\n",
      "\n",
      "During handling of the above exception, another exception occurred:\n",
      "\n",
      "Traceback (most recent call last):\n",
      "  File \"/home/bschroed/anaconda3/envs/pyGromosTools/lib/python3.7/site-packages/IPython/core/interactiveshell.py\", line 3441, in run_code\n",
      "    exec(code_obj, self.user_global_ns, self.user_ns)\n",
      "  File \"<ipython-input-12-b3615fac4e85>\", line 5, in <module>\n",
      "    trc = Trc(input_value=in_path)\n",
      "  File \"/home/bschroed/Documents/projects/PyGromosTools/pygromos/files/trajectory/trc.py\", line 32, in __init__\n",
      "    super().__init__(input_value, auto_save=auto_save, stride=stride, skip=skip)\n",
      "  File \"/home/bschroed/Documents/projects/PyGromosTools/pygromos/files/trajectory/_general_trajectory.py\", line 48, in __init__\n",
      "    self._read_from_file(input_path=input_value, auto_save=auto_save, stride=stride, skip=skip)\n",
      "  File \"/home/bschroed/Documents/projects/PyGromosTools/pygromos/files/trajectory/_general_trajectory.py\", line 136, in _read_from_file\n",
      "    self._read_db_from_hf5(input_path=input_path)\n",
      "  File \"/home/bschroed/Documents/projects/PyGromosTools/pygromos/files/trajectory/_general_trajectory.py\", line 144, in _read_db_from_hf5\n",
      "    self.database = pandas.read_hdf(path_or_buf=input_path, key=input_path.split(\".\")[-1])\n",
      "  File \"/home/bschroed/anaconda3/envs/pyGromosTools/lib/python3.7/site-packages/pandas/io/pytables.py\", line 399, in read_hdf\n",
      "    store = HDFStore(path_or_buf, mode=mode, errors=errors, **kwargs)\n",
      "  File \"/home/bschroed/anaconda3/envs/pyGromosTools/lib/python3.7/site-packages/pandas/io/pytables.py\", line 542, in __init__\n",
      "    tables = import_optional_dependency(\"tables\")\n",
      "  File \"/home/bschroed/anaconda3/envs/pyGromosTools/lib/python3.7/site-packages/pandas/compat/_optional.py\", line 106, in import_optional_dependency\n",
      "    module = importlib.import_module(name)\n",
      "  File \"/home/bschroed/anaconda3/envs/pyGromosTools/lib/python3.7/importlib/__init__.py\", line 127, in import_module\n",
      "    return _bootstrap._gcd_import(name[level:], package, level)\n",
      "  File \"<frozen importlib._bootstrap>\", line 1006, in _gcd_import\n",
      "  File \"<frozen importlib._bootstrap>\", line 983, in _find_and_load\n",
      "  File \"<frozen importlib._bootstrap>\", line 967, in _find_and_load_unlocked\n",
      "  File \"<frozen importlib._bootstrap>\", line 677, in _load_unlocked\n",
      "  File \"<frozen importlib._bootstrap_external>\", line 728, in exec_module\n",
      "  File \"<frozen importlib._bootstrap>\", line 219, in _call_with_frames_removed\n",
      "  File \"/home/bschroed/anaconda3/envs/pyGromosTools/lib/python3.7/site-packages/tables/__init__.py\", line 148, in <module>\n",
      "    from .tests import print_versions, test\n",
      "  File \"/home/bschroed/anaconda3/envs/pyGromosTools/lib/python3.7/site-packages/tables/tests/__init__.py\", line 21, in <module>\n",
      "    from tables.tests.common import print_versions\n",
      "  File \"/home/bschroed/anaconda3/envs/pyGromosTools/lib/python3.7/site-packages/tables/tests/common.py\", line 25, in <module>\n",
      "    from pkg_resources import resource_filename\n",
      "  File \"/home/bschroed/anaconda3/envs/pyGromosTools/lib/python3.7/site-packages/pkg_resources/__init__.py\", line 3242, in <module>\n",
      "    @_call_aside\n",
      "  File \"/home/bschroed/anaconda3/envs/pyGromosTools/lib/python3.7/site-packages/pkg_resources/__init__.py\", line 3226, in _call_aside\n",
      "    f(*args, **kwargs)\n",
      "  File \"/home/bschroed/anaconda3/envs/pyGromosTools/lib/python3.7/site-packages/pkg_resources/__init__.py\", line 3255, in _initialize_master_working_set\n",
      "    working_set = WorkingSet._build_master()\n",
      "  File \"/home/bschroed/anaconda3/envs/pyGromosTools/lib/python3.7/site-packages/pkg_resources/__init__.py\", line 559, in _build_master\n",
      "    ws = cls()\n",
      "  File \"/home/bschroed/anaconda3/envs/pyGromosTools/lib/python3.7/site-packages/pkg_resources/__init__.py\", line 552, in __init__\n",
      "    self.add_entry(entry)\n",
      "  File \"/home/bschroed/anaconda3/envs/pyGromosTools/lib/python3.7/site-packages/pkg_resources/__init__.py\", line 608, in add_entry\n",
      "    for dist in find_distributions(entry, True):\n",
      "  File \"/home/bschroed/anaconda3/envs/pyGromosTools/lib/python3.7/site-packages/pkg_resources/__init__.py\", line 1964, in find_distributions\n",
      "    importer = get_importer(path_item)\n",
      "  File \"/home/bschroed/anaconda3/envs/pyGromosTools/lib/python3.7/pkgutil.py\", line 419, in get_importer\n",
      "    importer = path_hook(path_item)\n",
      "  File \"<frozen importlib._bootstrap_external>\", line 1447, in path_hook_for_FileFinder\n",
      "  File \"<frozen importlib._bootstrap_external>\", line 101, in _path_isdir\n",
      "FileNotFoundError: [Errno 2] No such file or directory\n",
      "\n",
      "During handling of the above exception, another exception occurred:\n",
      "\n",
      "Traceback (most recent call last):\n",
      "  File \"/home/bschroed/anaconda3/envs/pyGromosTools/lib/python3.7/site-packages/IPython/core/interactiveshell.py\", line 2061, in showtraceback\n",
      "    stb = value._render_traceback_()\n",
      "AttributeError: 'FileNotFoundError' object has no attribute '_render_traceback_'\n",
      "\n",
      "During handling of the above exception, another exception occurred:\n",
      "\n",
      "Traceback (most recent call last):\n",
      "  File \"/home/bschroed/anaconda3/envs/pyGromosTools/lib/python3.7/site-packages/IPython/core/ultratb.py\", line 1101, in get_records\n",
      "    return _fixed_getinnerframes(etb, number_of_lines_of_context, tb_offset)\n",
      "  File \"/home/bschroed/anaconda3/envs/pyGromosTools/lib/python3.7/site-packages/IPython/core/ultratb.py\", line 248, in wrapped\n",
      "    return f(*args, **kwargs)\n",
      "  File \"/home/bschroed/anaconda3/envs/pyGromosTools/lib/python3.7/site-packages/IPython/core/ultratb.py\", line 281, in _fixed_getinnerframes\n",
      "    records = fix_frame_records_filenames(inspect.getinnerframes(etb, context))\n",
      "  File \"/home/bschroed/anaconda3/envs/pyGromosTools/lib/python3.7/inspect.py\", line 1502, in getinnerframes\n",
      "    frameinfo = (tb.tb_frame,) + getframeinfo(tb, context)\n",
      "  File \"/home/bschroed/anaconda3/envs/pyGromosTools/lib/python3.7/inspect.py\", line 1460, in getframeinfo\n",
      "    filename = getsourcefile(frame) or getfile(frame)\n",
      "  File \"/home/bschroed/anaconda3/envs/pyGromosTools/lib/python3.7/inspect.py\", line 696, in getsourcefile\n",
      "    if getattr(getmodule(object, filename), '__loader__', None) is not None:\n",
      "  File \"/home/bschroed/anaconda3/envs/pyGromosTools/lib/python3.7/inspect.py\", line 725, in getmodule\n",
      "    file = getabsfile(object, _filename)\n",
      "  File \"/home/bschroed/anaconda3/envs/pyGromosTools/lib/python3.7/inspect.py\", line 709, in getabsfile\n",
      "    return os.path.normcase(os.path.abspath(_filename))\n",
      "  File \"/home/bschroed/anaconda3/envs/pyGromosTools/lib/python3.7/posixpath.py\", line 383, in abspath\n",
      "    cwd = os.getcwd()\n",
      "FileNotFoundError: [Errno 2] No such file or directory\n",
      "Traceback (most recent call last):\n",
      "  File \"/home/bschroed/anaconda3/envs/pyGromosTools/lib/python3.7/pkgutil.py\", line 415, in get_importer\n",
      "    importer = sys.path_importer_cache[path_item]\n",
      "KeyError: ''\n",
      "\n",
      "During handling of the above exception, another exception occurred:\n",
      "\n",
      "Traceback (most recent call last):\n",
      "  File \"/home/bschroed/anaconda3/envs/pyGromosTools/lib/python3.7/site-packages/IPython/core/interactiveshell.py\", line 3441, in run_code\n",
      "    exec(code_obj, self.user_global_ns, self.user_ns)\n",
      "  File \"<ipython-input-12-b3615fac4e85>\", line 5, in <module>\n",
      "    trc = Trc(input_value=in_path)\n",
      "  File \"/home/bschroed/Documents/projects/PyGromosTools/pygromos/files/trajectory/trc.py\", line 32, in __init__\n",
      "    super().__init__(input_value, auto_save=auto_save, stride=stride, skip=skip)\n",
      "  File \"/home/bschroed/Documents/projects/PyGromosTools/pygromos/files/trajectory/_general_trajectory.py\", line 48, in __init__\n",
      "    self._read_from_file(input_path=input_value, auto_save=auto_save, stride=stride, skip=skip)\n",
      "  File \"/home/bschroed/Documents/projects/PyGromosTools/pygromos/files/trajectory/_general_trajectory.py\", line 136, in _read_from_file\n",
      "    self._read_db_from_hf5(input_path=input_path)\n",
      "  File \"/home/bschroed/Documents/projects/PyGromosTools/pygromos/files/trajectory/_general_trajectory.py\", line 144, in _read_db_from_hf5\n",
      "    self.database = pandas.read_hdf(path_or_buf=input_path, key=input_path.split(\".\")[-1])\n",
      "  File \"/home/bschroed/anaconda3/envs/pyGromosTools/lib/python3.7/site-packages/pandas/io/pytables.py\", line 399, in read_hdf\n",
      "    store = HDFStore(path_or_buf, mode=mode, errors=errors, **kwargs)\n",
      "  File \"/home/bschroed/anaconda3/envs/pyGromosTools/lib/python3.7/site-packages/pandas/io/pytables.py\", line 542, in __init__\n",
      "    tables = import_optional_dependency(\"tables\")\n",
      "  File \"/home/bschroed/anaconda3/envs/pyGromosTools/lib/python3.7/site-packages/pandas/compat/_optional.py\", line 106, in import_optional_dependency\n",
      "    module = importlib.import_module(name)\n",
      "  File \"/home/bschroed/anaconda3/envs/pyGromosTools/lib/python3.7/importlib/__init__.py\", line 127, in import_module\n",
      "    return _bootstrap._gcd_import(name[level:], package, level)\n",
      "  File \"<frozen importlib._bootstrap>\", line 1006, in _gcd_import\n",
      "  File \"<frozen importlib._bootstrap>\", line 983, in _find_and_load\n",
      "  File \"<frozen importlib._bootstrap>\", line 967, in _find_and_load_unlocked\n",
      "  File \"<frozen importlib._bootstrap>\", line 677, in _load_unlocked\n",
      "  File \"<frozen importlib._bootstrap_external>\", line 728, in exec_module\n",
      "  File \"<frozen importlib._bootstrap>\", line 219, in _call_with_frames_removed\n",
      "  File \"/home/bschroed/anaconda3/envs/pyGromosTools/lib/python3.7/site-packages/tables/__init__.py\", line 148, in <module>\n",
      "    from .tests import print_versions, test\n",
      "  File \"/home/bschroed/anaconda3/envs/pyGromosTools/lib/python3.7/site-packages/tables/tests/__init__.py\", line 21, in <module>\n",
      "    from tables.tests.common import print_versions\n",
      "  File \"/home/bschroed/anaconda3/envs/pyGromosTools/lib/python3.7/site-packages/tables/tests/common.py\", line 25, in <module>\n",
      "    from pkg_resources import resource_filename\n",
      "  File \"/home/bschroed/anaconda3/envs/pyGromosTools/lib/python3.7/site-packages/pkg_resources/__init__.py\", line 3242, in <module>\n",
      "    @_call_aside\n",
      "  File \"/home/bschroed/anaconda3/envs/pyGromosTools/lib/python3.7/site-packages/pkg_resources/__init__.py\", line 3226, in _call_aside\n",
      "    f(*args, **kwargs)\n",
      "  File \"/home/bschroed/anaconda3/envs/pyGromosTools/lib/python3.7/site-packages/pkg_resources/__init__.py\", line 3255, in _initialize_master_working_set\n",
      "    working_set = WorkingSet._build_master()\n",
      "  File \"/home/bschroed/anaconda3/envs/pyGromosTools/lib/python3.7/site-packages/pkg_resources/__init__.py\", line 559, in _build_master\n",
      "    ws = cls()\n",
      "  File \"/home/bschroed/anaconda3/envs/pyGromosTools/lib/python3.7/site-packages/pkg_resources/__init__.py\", line 552, in __init__\n",
      "    self.add_entry(entry)\n",
      "  File \"/home/bschroed/anaconda3/envs/pyGromosTools/lib/python3.7/site-packages/pkg_resources/__init__.py\", line 608, in add_entry\n",
      "    for dist in find_distributions(entry, True):\n",
      "  File \"/home/bschroed/anaconda3/envs/pyGromosTools/lib/python3.7/site-packages/pkg_resources/__init__.py\", line 1964, in find_distributions\n",
      "    importer = get_importer(path_item)\n",
      "  File \"/home/bschroed/anaconda3/envs/pyGromosTools/lib/python3.7/pkgutil.py\", line 419, in get_importer\n",
      "    importer = path_hook(path_item)\n",
      "  File \"<frozen importlib._bootstrap_external>\", line 1447, in path_hook_for_FileFinder\n",
      "  File \"<frozen importlib._bootstrap_external>\", line 101, in _path_isdir\n",
      "FileNotFoundError: [Errno 2] No such file or directory\n",
      "\n",
      "During handling of the above exception, another exception occurred:\n",
      "\n",
      "Traceback (most recent call last):\n",
      "  File \"/home/bschroed/anaconda3/envs/pyGromosTools/lib/python3.7/site-packages/IPython/core/interactiveshell.py\", line 2061, in showtraceback\n",
      "    stb = value._render_traceback_()\n",
      "AttributeError: 'FileNotFoundError' object has no attribute '_render_traceback_'\n",
      "\n",
      "During handling of the above exception, another exception occurred:\n",
      "\n",
      "Traceback (most recent call last):\n",
      "  File \"/home/bschroed/anaconda3/envs/pyGromosTools/lib/python3.7/site-packages/IPython/core/interactiveshell.py\", line 3361, in run_ast_nodes\n",
      "    if (await self.run_code(code, result,  async_=asy)):\n",
      "  File \"/home/bschroed/anaconda3/envs/pyGromosTools/lib/python3.7/site-packages/IPython/core/interactiveshell.py\", line 3458, in run_code\n",
      "    self.showtraceback(running_compiled_code=True)\n",
      "  File \"/home/bschroed/anaconda3/envs/pyGromosTools/lib/python3.7/site-packages/IPython/core/interactiveshell.py\", line 2064, in showtraceback\n",
      "    value, tb, tb_offset=tb_offset)\n",
      "  File \"/home/bschroed/anaconda3/envs/pyGromosTools/lib/python3.7/site-packages/IPython/core/ultratb.py\", line 1368, in structured_traceback\n",
      "    self, etype, value, tb, tb_offset, number_of_lines_of_context)\n",
      "  File \"/home/bschroed/anaconda3/envs/pyGromosTools/lib/python3.7/site-packages/IPython/core/ultratb.py\", line 1268, in structured_traceback\n",
      "    self, etype, value, tb, tb_offset, number_of_lines_of_context\n",
      "  File \"/home/bschroed/anaconda3/envs/pyGromosTools/lib/python3.7/site-packages/IPython/core/ultratb.py\", line 1125, in structured_traceback\n",
      "    tb_offset)\n",
      "  File \"/home/bschroed/anaconda3/envs/pyGromosTools/lib/python3.7/site-packages/IPython/core/ultratb.py\", line 1082, in format_exception_as_a_whole\n",
      "    last_unique, recursion_repeat = find_recursion(orig_etype, evalue, records)\n",
      "  File \"/home/bschroed/anaconda3/envs/pyGromosTools/lib/python3.7/site-packages/IPython/core/ultratb.py\", line 382, in find_recursion\n",
      "    return len(records), 0\n",
      "TypeError: object of type 'NoneType' has no len()\n",
      "\n",
      "During handling of the above exception, another exception occurred:\n",
      "\n",
      "Traceback (most recent call last):\n",
      "  File \"/home/bschroed/anaconda3/envs/pyGromosTools/lib/python3.7/site-packages/IPython/core/interactiveshell.py\", line 2061, in showtraceback\n",
      "    stb = value._render_traceback_()\n",
      "AttributeError: 'TypeError' object has no attribute '_render_traceback_'\n",
      "\n",
      "During handling of the above exception, another exception occurred:\n",
      "\n",
      "Traceback (most recent call last):\n",
      "  File \"/home/bschroed/anaconda3/envs/pyGromosTools/lib/python3.7/site-packages/IPython/core/ultratb.py\", line 1101, in get_records\n",
      "    return _fixed_getinnerframes(etb, number_of_lines_of_context, tb_offset)\n",
      "  File \"/home/bschroed/anaconda3/envs/pyGromosTools/lib/python3.7/site-packages/IPython/core/ultratb.py\", line 248, in wrapped\n",
      "    return f(*args, **kwargs)\n",
      "  File \"/home/bschroed/anaconda3/envs/pyGromosTools/lib/python3.7/site-packages/IPython/core/ultratb.py\", line 281, in _fixed_getinnerframes\n",
      "    records = fix_frame_records_filenames(inspect.getinnerframes(etb, context))\n",
      "  File \"/home/bschroed/anaconda3/envs/pyGromosTools/lib/python3.7/inspect.py\", line 1502, in getinnerframes\n",
      "    frameinfo = (tb.tb_frame,) + getframeinfo(tb, context)\n",
      "  File \"/home/bschroed/anaconda3/envs/pyGromosTools/lib/python3.7/inspect.py\", line 1460, in getframeinfo\n",
      "    filename = getsourcefile(frame) or getfile(frame)\n",
      "  File \"/home/bschroed/anaconda3/envs/pyGromosTools/lib/python3.7/inspect.py\", line 696, in getsourcefile\n",
      "    if getattr(getmodule(object, filename), '__loader__', None) is not None:\n",
      "  File \"/home/bschroed/anaconda3/envs/pyGromosTools/lib/python3.7/inspect.py\", line 725, in getmodule\n",
      "    file = getabsfile(object, _filename)\n",
      "  File \"/home/bschroed/anaconda3/envs/pyGromosTools/lib/python3.7/inspect.py\", line 709, in getabsfile\n",
      "    return os.path.normcase(os.path.abspath(_filename))\n",
      "  File \"/home/bschroed/anaconda3/envs/pyGromosTools/lib/python3.7/posixpath.py\", line 383, in abspath\n",
      "    cwd = os.getcwd()\n",
      "FileNotFoundError: [Errno 2] No such file or directory\n",
      "Traceback (most recent call last):\n",
      "  File \"/home/bschroed/anaconda3/envs/pyGromosTools/lib/python3.7/pkgutil.py\", line 415, in get_importer\n",
      "    importer = sys.path_importer_cache[path_item]\n",
      "KeyError: ''\n",
      "\n",
      "During handling of the above exception, another exception occurred:\n",
      "\n",
      "Traceback (most recent call last):\n",
      "  File \"/home/bschroed/anaconda3/envs/pyGromosTools/lib/python3.7/site-packages/IPython/core/interactiveshell.py\", line 3441, in run_code\n",
      "    exec(code_obj, self.user_global_ns, self.user_ns)\n",
      "  File \"<ipython-input-12-b3615fac4e85>\", line 5, in <module>\n",
      "    trc = Trc(input_value=in_path)\n",
      "  File \"/home/bschroed/Documents/projects/PyGromosTools/pygromos/files/trajectory/trc.py\", line 32, in __init__\n",
      "    super().__init__(input_value, auto_save=auto_save, stride=stride, skip=skip)\n",
      "  File \"/home/bschroed/Documents/projects/PyGromosTools/pygromos/files/trajectory/_general_trajectory.py\", line 48, in __init__\n",
      "    self._read_from_file(input_path=input_value, auto_save=auto_save, stride=stride, skip=skip)\n",
      "  File \"/home/bschroed/Documents/projects/PyGromosTools/pygromos/files/trajectory/_general_trajectory.py\", line 136, in _read_from_file\n",
      "    self._read_db_from_hf5(input_path=input_path)\n",
      "  File \"/home/bschroed/Documents/projects/PyGromosTools/pygromos/files/trajectory/_general_trajectory.py\", line 144, in _read_db_from_hf5\n",
      "    self.database = pandas.read_hdf(path_or_buf=input_path, key=input_path.split(\".\")[-1])\n",
      "  File \"/home/bschroed/anaconda3/envs/pyGromosTools/lib/python3.7/site-packages/pandas/io/pytables.py\", line 399, in read_hdf\n",
      "    store = HDFStore(path_or_buf, mode=mode, errors=errors, **kwargs)\n",
      "  File \"/home/bschroed/anaconda3/envs/pyGromosTools/lib/python3.7/site-packages/pandas/io/pytables.py\", line 542, in __init__\n",
      "    tables = import_optional_dependency(\"tables\")\n",
      "  File \"/home/bschroed/anaconda3/envs/pyGromosTools/lib/python3.7/site-packages/pandas/compat/_optional.py\", line 106, in import_optional_dependency\n",
      "    module = importlib.import_module(name)\n",
      "  File \"/home/bschroed/anaconda3/envs/pyGromosTools/lib/python3.7/importlib/__init__.py\", line 127, in import_module\n",
      "    return _bootstrap._gcd_import(name[level:], package, level)\n",
      "  File \"<frozen importlib._bootstrap>\", line 1006, in _gcd_import\n",
      "  File \"<frozen importlib._bootstrap>\", line 983, in _find_and_load\n",
      "  File \"<frozen importlib._bootstrap>\", line 967, in _find_and_load_unlocked\n",
      "  File \"<frozen importlib._bootstrap>\", line 677, in _load_unlocked\n",
      "  File \"<frozen importlib._bootstrap_external>\", line 728, in exec_module\n",
      "  File \"<frozen importlib._bootstrap>\", line 219, in _call_with_frames_removed\n",
      "  File \"/home/bschroed/anaconda3/envs/pyGromosTools/lib/python3.7/site-packages/tables/__init__.py\", line 148, in <module>\n",
      "    from .tests import print_versions, test\n",
      "  File \"/home/bschroed/anaconda3/envs/pyGromosTools/lib/python3.7/site-packages/tables/tests/__init__.py\", line 21, in <module>\n",
      "    from tables.tests.common import print_versions\n",
      "  File \"/home/bschroed/anaconda3/envs/pyGromosTools/lib/python3.7/site-packages/tables/tests/common.py\", line 25, in <module>\n",
      "    from pkg_resources import resource_filename\n",
      "  File \"/home/bschroed/anaconda3/envs/pyGromosTools/lib/python3.7/site-packages/pkg_resources/__init__.py\", line 3242, in <module>\n",
      "    @_call_aside\n",
      "  File \"/home/bschroed/anaconda3/envs/pyGromosTools/lib/python3.7/site-packages/pkg_resources/__init__.py\", line 3226, in _call_aside\n",
      "    f(*args, **kwargs)\n",
      "  File \"/home/bschroed/anaconda3/envs/pyGromosTools/lib/python3.7/site-packages/pkg_resources/__init__.py\", line 3255, in _initialize_master_working_set\n",
      "    working_set = WorkingSet._build_master()\n",
      "  File \"/home/bschroed/anaconda3/envs/pyGromosTools/lib/python3.7/site-packages/pkg_resources/__init__.py\", line 559, in _build_master\n",
      "    ws = cls()\n",
      "  File \"/home/bschroed/anaconda3/envs/pyGromosTools/lib/python3.7/site-packages/pkg_resources/__init__.py\", line 552, in __init__\n",
      "    self.add_entry(entry)\n",
      "  File \"/home/bschroed/anaconda3/envs/pyGromosTools/lib/python3.7/site-packages/pkg_resources/__init__.py\", line 608, in add_entry\n",
      "    for dist in find_distributions(entry, True):\n",
      "  File \"/home/bschroed/anaconda3/envs/pyGromosTools/lib/python3.7/site-packages/pkg_resources/__init__.py\", line 1964, in find_distributions\n",
      "    importer = get_importer(path_item)\n",
      "  File \"/home/bschroed/anaconda3/envs/pyGromosTools/lib/python3.7/pkgutil.py\", line 419, in get_importer\n",
      "    importer = path_hook(path_item)\n",
      "  File \"<frozen importlib._bootstrap_external>\", line 1447, in path_hook_for_FileFinder\n",
      "  File \"<frozen importlib._bootstrap_external>\", line 101, in _path_isdir\n",
      "FileNotFoundError: [Errno 2] No such file or directory\n",
      "\n",
      "During handling of the above exception, another exception occurred:\n",
      "\n",
      "Traceback (most recent call last):\n",
      "  File \"/home/bschroed/anaconda3/envs/pyGromosTools/lib/python3.7/site-packages/IPython/core/interactiveshell.py\", line 2061, in showtraceback\n",
      "    stb = value._render_traceback_()\n",
      "AttributeError: 'FileNotFoundError' object has no attribute '_render_traceback_'\n",
      "\n",
      "During handling of the above exception, another exception occurred:\n",
      "\n",
      "Traceback (most recent call last):\n",
      "  File \"/home/bschroed/anaconda3/envs/pyGromosTools/lib/python3.7/site-packages/IPython/core/interactiveshell.py\", line 3361, in run_ast_nodes\n",
      "    if (await self.run_code(code, result,  async_=asy)):\n",
      "  File \"/home/bschroed/anaconda3/envs/pyGromosTools/lib/python3.7/site-packages/IPython/core/interactiveshell.py\", line 3458, in run_code\n",
      "    self.showtraceback(running_compiled_code=True)\n",
      "  File \"/home/bschroed/anaconda3/envs/pyGromosTools/lib/python3.7/site-packages/IPython/core/interactiveshell.py\", line 2064, in showtraceback\n",
      "    value, tb, tb_offset=tb_offset)\n",
      "  File \"/home/bschroed/anaconda3/envs/pyGromosTools/lib/python3.7/site-packages/IPython/core/ultratb.py\", line 1368, in structured_traceback\n",
      "    self, etype, value, tb, tb_offset, number_of_lines_of_context)\n",
      "  File \"/home/bschroed/anaconda3/envs/pyGromosTools/lib/python3.7/site-packages/IPython/core/ultratb.py\", line 1268, in structured_traceback\n",
      "    self, etype, value, tb, tb_offset, number_of_lines_of_context\n",
      "  File \"/home/bschroed/anaconda3/envs/pyGromosTools/lib/python3.7/site-packages/IPython/core/ultratb.py\", line 1125, in structured_traceback\n",
      "    tb_offset)\n",
      "  File \"/home/bschroed/anaconda3/envs/pyGromosTools/lib/python3.7/site-packages/IPython/core/ultratb.py\", line 1082, in format_exception_as_a_whole\n",
      "    last_unique, recursion_repeat = find_recursion(orig_etype, evalue, records)\n",
      "  File \"/home/bschroed/anaconda3/envs/pyGromosTools/lib/python3.7/site-packages/IPython/core/ultratb.py\", line 382, in find_recursion\n",
      "    return len(records), 0\n",
      "TypeError: object of type 'NoneType' has no len()\n",
      "\n",
      "During handling of the above exception, another exception occurred:\n",
      "\n",
      "Traceback (most recent call last):\n",
      "  File \"/home/bschroed/anaconda3/envs/pyGromosTools/lib/python3.7/site-packages/IPython/core/interactiveshell.py\", line 2061, in showtraceback\n",
      "    stb = value._render_traceback_()\n",
      "AttributeError: 'TypeError' object has no attribute '_render_traceback_'\n",
      "\n",
      "During handling of the above exception, another exception occurred:\n",
      "\n",
      "Traceback (most recent call last):\n",
      "  File \"/home/bschroed/anaconda3/envs/pyGromosTools/lib/python3.7/site-packages/IPython/core/interactiveshell.py\", line 2944, in _run_cell\n",
      "    return runner(coro)\n",
      "  File \"/home/bschroed/anaconda3/envs/pyGromosTools/lib/python3.7/site-packages/IPython/core/async_helpers.py\", line 68, in _pseudo_sync_runner\n",
      "    coro.send(None)\n",
      "  File \"/home/bschroed/anaconda3/envs/pyGromosTools/lib/python3.7/site-packages/IPython/core/interactiveshell.py\", line 3170, in run_cell_async\n",
      "    interactivity=interactivity, compiler=compiler, result=result)\n",
      "  File \"/home/bschroed/anaconda3/envs/pyGromosTools/lib/python3.7/site-packages/IPython/core/interactiveshell.py\", line 3380, in run_ast_nodes\n",
      "    self.showtraceback()\n",
      "  File \"/home/bschroed/anaconda3/envs/pyGromosTools/lib/python3.7/site-packages/IPython/core/interactiveshell.py\", line 2064, in showtraceback\n",
      "    value, tb, tb_offset=tb_offset)\n",
      "  File \"/home/bschroed/anaconda3/envs/pyGromosTools/lib/python3.7/site-packages/IPython/core/ultratb.py\", line 1368, in structured_traceback\n",
      "    self, etype, value, tb, tb_offset, number_of_lines_of_context)\n",
      "  File \"/home/bschroed/anaconda3/envs/pyGromosTools/lib/python3.7/site-packages/IPython/core/ultratb.py\", line 1268, in structured_traceback\n",
      "    self, etype, value, tb, tb_offset, number_of_lines_of_context\n",
      "  File \"/home/bschroed/anaconda3/envs/pyGromosTools/lib/python3.7/site-packages/IPython/core/ultratb.py\", line 1143, in structured_traceback\n",
      "    chained_exceptions_tb_offset)\n",
      "  File \"/home/bschroed/anaconda3/envs/pyGromosTools/lib/python3.7/site-packages/IPython/core/ultratb.py\", line 1082, in format_exception_as_a_whole\n",
      "    last_unique, recursion_repeat = find_recursion(orig_etype, evalue, records)\n",
      "  File \"/home/bschroed/anaconda3/envs/pyGromosTools/lib/python3.7/site-packages/IPython/core/ultratb.py\", line 382, in find_recursion\n",
      "    return len(records), 0\n",
      "TypeError: object of type 'NoneType' has no len()\n",
      "\n",
      "During handling of the above exception, another exception occurred:\n",
      "\n",
      "Traceback (most recent call last):\n",
      "  File \"/home/bschroed/anaconda3/envs/pyGromosTools/lib/python3.7/site-packages/IPython/core/interactiveshell.py\", line 2061, in showtraceback\n",
      "    stb = value._render_traceback_()\n",
      "AttributeError: 'TypeError' object has no attribute '_render_traceback_'\n",
      "\n",
      "During handling of the above exception, another exception occurred:\n",
      "\n",
      "Traceback (most recent call last):\n",
      "  File \"/home/bschroed/anaconda3/envs/pyGromosTools/lib/python3.7/site-packages/IPython/core/ultratb.py\", line 1101, in get_records\n",
      "    return _fixed_getinnerframes(etb, number_of_lines_of_context, tb_offset)\n",
      "  File \"/home/bschroed/anaconda3/envs/pyGromosTools/lib/python3.7/site-packages/IPython/core/ultratb.py\", line 248, in wrapped\n",
      "    return f(*args, **kwargs)\n",
      "  File \"/home/bschroed/anaconda3/envs/pyGromosTools/lib/python3.7/site-packages/IPython/core/ultratb.py\", line 281, in _fixed_getinnerframes\n",
      "    records = fix_frame_records_filenames(inspect.getinnerframes(etb, context))\n",
      "  File \"/home/bschroed/anaconda3/envs/pyGromosTools/lib/python3.7/inspect.py\", line 1502, in getinnerframes\n",
      "    frameinfo = (tb.tb_frame,) + getframeinfo(tb, context)\n",
      "  File \"/home/bschroed/anaconda3/envs/pyGromosTools/lib/python3.7/inspect.py\", line 1460, in getframeinfo\n",
      "    filename = getsourcefile(frame) or getfile(frame)\n",
      "  File \"/home/bschroed/anaconda3/envs/pyGromosTools/lib/python3.7/inspect.py\", line 696, in getsourcefile\n",
      "    if getattr(getmodule(object, filename), '__loader__', None) is not None:\n",
      "  File \"/home/bschroed/anaconda3/envs/pyGromosTools/lib/python3.7/inspect.py\", line 725, in getmodule\n",
      "    file = getabsfile(object, _filename)\n",
      "  File \"/home/bschroed/anaconda3/envs/pyGromosTools/lib/python3.7/inspect.py\", line 709, in getabsfile\n",
      "    return os.path.normcase(os.path.abspath(_filename))\n",
      "  File \"/home/bschroed/anaconda3/envs/pyGromosTools/lib/python3.7/posixpath.py\", line 383, in abspath\n",
      "    cwd = os.getcwd()\n",
      "FileNotFoundError: [Errno 2] No such file or directory\n"
     ]
    }
   ],
   "source": [
    "from pygromos.files.trajectory.trc import Trc\n",
    "\n",
    "in_path=project_dir+\"/b_vacuum_sd/analysis/data/b_vacuum_sd.trc.h5\"\n",
    "\n",
    "trc = Trc(input_value=in_path)\n",
    "trc.write_pdb(out_ana+\"/sd_traj.pdb\", cnf_file=cnf_path)#grom_system.cnf.path)\n",
    "trc"
   ]
  },
  {
   "cell_type": "code",
   "execution_count": null,
   "metadata": {
    "pycharm": {
     "name": "#%%\n"
    }
   },
   "outputs": [
    {
     "name": "stderr",
     "output_type": "stream",
     "text": [
      "ERROR:root:Internal Python error in the inspect module.\n",
      "Below is the traceback from this internal error.\n",
      "\n",
      "ERROR:root:Internal Python error in the inspect module.\n",
      "Below is the traceback from this internal error.\n",
      "\n",
      "ERROR:root:Internal Python error in the inspect module.\n",
      "Below is the traceback from this internal error.\n",
      "\n"
     ]
    },
    {
     "name": "stdout",
     "output_type": "stream",
     "text": [
      "ERROR! Session/line number was not unique in database. History logging moved to new session 171\n",
      "Traceback (most recent call last):\n",
      "  File \"/home/bschroed/anaconda3/envs/pyGromosTools/lib/python3.7/pkgutil.py\", line 415, in get_importer\n",
      "    importer = sys.path_importer_cache[path_item]\n",
      "KeyError: ''\n",
      "\n",
      "During handling of the above exception, another exception occurred:\n",
      "\n",
      "Traceback (most recent call last):\n",
      "  File \"/home/bschroed/anaconda3/envs/pyGromosTools/lib/python3.7/site-packages/IPython/core/interactiveshell.py\", line 3441, in run_code\n",
      "    exec(code_obj, self.user_global_ns, self.user_ns)\n",
      "  File \"<ipython-input-12-38475b66d665>\", line 5, in <module>\n",
      "    tre = Tre(input_value=in_path)\n",
      "  File \"/home/bschroed/Documents/projects/PyGromosTools/pygromos/files/trajectory/tre.py\", line 28, in __init__\n",
      "    super().__init__(input_value, auto_save=auto_save, stride=stride, skip=skip)\n",
      "  File \"/home/bschroed/Documents/projects/PyGromosTools/pygromos/files/trajectory/_general_trajectory.py\", line 48, in __init__\n",
      "    self._read_from_file(input_path=input_value, auto_save=auto_save, stride=stride, skip=skip)\n",
      "  File \"/home/bschroed/Documents/projects/PyGromosTools/pygromos/files/trajectory/_general_trajectory.py\", line 136, in _read_from_file\n",
      "    self._read_db_from_hf5(input_path=input_path)\n",
      "  File \"/home/bschroed/Documents/projects/PyGromosTools/pygromos/files/trajectory/_general_trajectory.py\", line 144, in _read_db_from_hf5\n",
      "    self.database = pandas.read_hdf(path_or_buf=input_path, key=input_path.split(\".\")[-1])\n",
      "  File \"/home/bschroed/anaconda3/envs/pyGromosTools/lib/python3.7/site-packages/pandas/io/pytables.py\", line 399, in read_hdf\n",
      "    store = HDFStore(path_or_buf, mode=mode, errors=errors, **kwargs)\n",
      "  File \"/home/bschroed/anaconda3/envs/pyGromosTools/lib/python3.7/site-packages/pandas/io/pytables.py\", line 542, in __init__\n",
      "    tables = import_optional_dependency(\"tables\")\n",
      "  File \"/home/bschroed/anaconda3/envs/pyGromosTools/lib/python3.7/site-packages/pandas/compat/_optional.py\", line 106, in import_optional_dependency\n",
      "    module = importlib.import_module(name)\n",
      "  File \"/home/bschroed/anaconda3/envs/pyGromosTools/lib/python3.7/importlib/__init__.py\", line 127, in import_module\n",
      "    return _bootstrap._gcd_import(name[level:], package, level)\n",
      "  File \"<frozen importlib._bootstrap>\", line 1006, in _gcd_import\n",
      "  File \"<frozen importlib._bootstrap>\", line 983, in _find_and_load\n",
      "  File \"<frozen importlib._bootstrap>\", line 967, in _find_and_load_unlocked\n",
      "  File \"<frozen importlib._bootstrap>\", line 677, in _load_unlocked\n",
      "  File \"<frozen importlib._bootstrap_external>\", line 728, in exec_module\n",
      "  File \"<frozen importlib._bootstrap>\", line 219, in _call_with_frames_removed\n",
      "  File \"/home/bschroed/anaconda3/envs/pyGromosTools/lib/python3.7/site-packages/tables/__init__.py\", line 148, in <module>\n",
      "    from .tests import print_versions, test\n",
      "  File \"/home/bschroed/anaconda3/envs/pyGromosTools/lib/python3.7/site-packages/tables/tests/__init__.py\", line 21, in <module>\n",
      "    from tables.tests.common import print_versions\n",
      "  File \"/home/bschroed/anaconda3/envs/pyGromosTools/lib/python3.7/site-packages/tables/tests/common.py\", line 25, in <module>\n",
      "    from pkg_resources import resource_filename\n",
      "  File \"/home/bschroed/anaconda3/envs/pyGromosTools/lib/python3.7/site-packages/pkg_resources/__init__.py\", line 3242, in <module>\n",
      "    @_call_aside\n",
      "  File \"/home/bschroed/anaconda3/envs/pyGromosTools/lib/python3.7/site-packages/pkg_resources/__init__.py\", line 3226, in _call_aside\n",
      "    f(*args, **kwargs)\n",
      "  File \"/home/bschroed/anaconda3/envs/pyGromosTools/lib/python3.7/site-packages/pkg_resources/__init__.py\", line 3255, in _initialize_master_working_set\n",
      "    working_set = WorkingSet._build_master()\n",
      "  File \"/home/bschroed/anaconda3/envs/pyGromosTools/lib/python3.7/site-packages/pkg_resources/__init__.py\", line 559, in _build_master\n",
      "    ws = cls()\n",
      "  File \"/home/bschroed/anaconda3/envs/pyGromosTools/lib/python3.7/site-packages/pkg_resources/__init__.py\", line 552, in __init__\n",
      "    self.add_entry(entry)\n",
      "  File \"/home/bschroed/anaconda3/envs/pyGromosTools/lib/python3.7/site-packages/pkg_resources/__init__.py\", line 608, in add_entry\n",
      "    for dist in find_distributions(entry, True):\n",
      "  File \"/home/bschroed/anaconda3/envs/pyGromosTools/lib/python3.7/site-packages/pkg_resources/__init__.py\", line 1964, in find_distributions\n",
      "    importer = get_importer(path_item)\n",
      "  File \"/home/bschroed/anaconda3/envs/pyGromosTools/lib/python3.7/pkgutil.py\", line 419, in get_importer\n",
      "    importer = path_hook(path_item)\n",
      "  File \"<frozen importlib._bootstrap_external>\", line 1447, in path_hook_for_FileFinder\n",
      "  File \"<frozen importlib._bootstrap_external>\", line 101, in _path_isdir\n",
      "FileNotFoundError: [Errno 2] No such file or directory\n",
      "\n",
      "During handling of the above exception, another exception occurred:\n",
      "\n",
      "Traceback (most recent call last):\n",
      "  File \"/home/bschroed/anaconda3/envs/pyGromosTools/lib/python3.7/site-packages/IPython/core/interactiveshell.py\", line 2061, in showtraceback\n",
      "    stb = value._render_traceback_()\n",
      "AttributeError: 'FileNotFoundError' object has no attribute '_render_traceback_'\n",
      "\n",
      "During handling of the above exception, another exception occurred:\n",
      "\n",
      "Traceback (most recent call last):\n",
      "  File \"/home/bschroed/anaconda3/envs/pyGromosTools/lib/python3.7/site-packages/IPython/core/ultratb.py\", line 1101, in get_records\n",
      "    return _fixed_getinnerframes(etb, number_of_lines_of_context, tb_offset)\n",
      "  File \"/home/bschroed/anaconda3/envs/pyGromosTools/lib/python3.7/site-packages/IPython/core/ultratb.py\", line 248, in wrapped\n",
      "    return f(*args, **kwargs)\n",
      "  File \"/home/bschroed/anaconda3/envs/pyGromosTools/lib/python3.7/site-packages/IPython/core/ultratb.py\", line 281, in _fixed_getinnerframes\n",
      "    records = fix_frame_records_filenames(inspect.getinnerframes(etb, context))\n",
      "  File \"/home/bschroed/anaconda3/envs/pyGromosTools/lib/python3.7/inspect.py\", line 1502, in getinnerframes\n",
      "    frameinfo = (tb.tb_frame,) + getframeinfo(tb, context)\n",
      "  File \"/home/bschroed/anaconda3/envs/pyGromosTools/lib/python3.7/inspect.py\", line 1460, in getframeinfo\n",
      "    filename = getsourcefile(frame) or getfile(frame)\n",
      "  File \"/home/bschroed/anaconda3/envs/pyGromosTools/lib/python3.7/inspect.py\", line 696, in getsourcefile\n",
      "    if getattr(getmodule(object, filename), '__loader__', None) is not None:\n",
      "  File \"/home/bschroed/anaconda3/envs/pyGromosTools/lib/python3.7/inspect.py\", line 725, in getmodule\n",
      "    file = getabsfile(object, _filename)\n",
      "  File \"/home/bschroed/anaconda3/envs/pyGromosTools/lib/python3.7/inspect.py\", line 709, in getabsfile\n",
      "    return os.path.normcase(os.path.abspath(_filename))\n",
      "  File \"/home/bschroed/anaconda3/envs/pyGromosTools/lib/python3.7/posixpath.py\", line 383, in abspath\n",
      "    cwd = os.getcwd()\n",
      "FileNotFoundError: [Errno 2] No such file or directory\n",
      "Traceback (most recent call last):\n",
      "  File \"/home/bschroed/anaconda3/envs/pyGromosTools/lib/python3.7/pkgutil.py\", line 415, in get_importer\n",
      "    importer = sys.path_importer_cache[path_item]\n",
      "KeyError: ''\n",
      "\n",
      "During handling of the above exception, another exception occurred:\n",
      "\n",
      "Traceback (most recent call last):\n",
      "  File \"/home/bschroed/anaconda3/envs/pyGromosTools/lib/python3.7/site-packages/IPython/core/interactiveshell.py\", line 3441, in run_code\n",
      "    exec(code_obj, self.user_global_ns, self.user_ns)\n",
      "  File \"<ipython-input-12-38475b66d665>\", line 5, in <module>\n",
      "    tre = Tre(input_value=in_path)\n",
      "  File \"/home/bschroed/Documents/projects/PyGromosTools/pygromos/files/trajectory/tre.py\", line 28, in __init__\n",
      "    super().__init__(input_value, auto_save=auto_save, stride=stride, skip=skip)\n",
      "  File \"/home/bschroed/Documents/projects/PyGromosTools/pygromos/files/trajectory/_general_trajectory.py\", line 48, in __init__\n",
      "    self._read_from_file(input_path=input_value, auto_save=auto_save, stride=stride, skip=skip)\n",
      "  File \"/home/bschroed/Documents/projects/PyGromosTools/pygromos/files/trajectory/_general_trajectory.py\", line 136, in _read_from_file\n",
      "    self._read_db_from_hf5(input_path=input_path)\n",
      "  File \"/home/bschroed/Documents/projects/PyGromosTools/pygromos/files/trajectory/_general_trajectory.py\", line 144, in _read_db_from_hf5\n",
      "    self.database = pandas.read_hdf(path_or_buf=input_path, key=input_path.split(\".\")[-1])\n",
      "  File \"/home/bschroed/anaconda3/envs/pyGromosTools/lib/python3.7/site-packages/pandas/io/pytables.py\", line 399, in read_hdf\n",
      "    store = HDFStore(path_or_buf, mode=mode, errors=errors, **kwargs)\n",
      "  File \"/home/bschroed/anaconda3/envs/pyGromosTools/lib/python3.7/site-packages/pandas/io/pytables.py\", line 542, in __init__\n",
      "    tables = import_optional_dependency(\"tables\")\n",
      "  File \"/home/bschroed/anaconda3/envs/pyGromosTools/lib/python3.7/site-packages/pandas/compat/_optional.py\", line 106, in import_optional_dependency\n",
      "    module = importlib.import_module(name)\n",
      "  File \"/home/bschroed/anaconda3/envs/pyGromosTools/lib/python3.7/importlib/__init__.py\", line 127, in import_module\n",
      "    return _bootstrap._gcd_import(name[level:], package, level)\n",
      "  File \"<frozen importlib._bootstrap>\", line 1006, in _gcd_import\n",
      "  File \"<frozen importlib._bootstrap>\", line 983, in _find_and_load\n",
      "  File \"<frozen importlib._bootstrap>\", line 967, in _find_and_load_unlocked\n",
      "  File \"<frozen importlib._bootstrap>\", line 677, in _load_unlocked\n",
      "  File \"<frozen importlib._bootstrap_external>\", line 728, in exec_module\n",
      "  File \"<frozen importlib._bootstrap>\", line 219, in _call_with_frames_removed\n",
      "  File \"/home/bschroed/anaconda3/envs/pyGromosTools/lib/python3.7/site-packages/tables/__init__.py\", line 148, in <module>\n",
      "    from .tests import print_versions, test\n",
      "  File \"/home/bschroed/anaconda3/envs/pyGromosTools/lib/python3.7/site-packages/tables/tests/__init__.py\", line 21, in <module>\n",
      "    from tables.tests.common import print_versions\n",
      "  File \"/home/bschroed/anaconda3/envs/pyGromosTools/lib/python3.7/site-packages/tables/tests/common.py\", line 25, in <module>\n",
      "    from pkg_resources import resource_filename\n",
      "  File \"/home/bschroed/anaconda3/envs/pyGromosTools/lib/python3.7/site-packages/pkg_resources/__init__.py\", line 3242, in <module>\n",
      "    @_call_aside\n",
      "  File \"/home/bschroed/anaconda3/envs/pyGromosTools/lib/python3.7/site-packages/pkg_resources/__init__.py\", line 3226, in _call_aside\n",
      "    f(*args, **kwargs)\n",
      "  File \"/home/bschroed/anaconda3/envs/pyGromosTools/lib/python3.7/site-packages/pkg_resources/__init__.py\", line 3255, in _initialize_master_working_set\n",
      "    working_set = WorkingSet._build_master()\n",
      "  File \"/home/bschroed/anaconda3/envs/pyGromosTools/lib/python3.7/site-packages/pkg_resources/__init__.py\", line 559, in _build_master\n",
      "    ws = cls()\n",
      "  File \"/home/bschroed/anaconda3/envs/pyGromosTools/lib/python3.7/site-packages/pkg_resources/__init__.py\", line 552, in __init__\n",
      "    self.add_entry(entry)\n",
      "  File \"/home/bschroed/anaconda3/envs/pyGromosTools/lib/python3.7/site-packages/pkg_resources/__init__.py\", line 608, in add_entry\n",
      "    for dist in find_distributions(entry, True):\n",
      "  File \"/home/bschroed/anaconda3/envs/pyGromosTools/lib/python3.7/site-packages/pkg_resources/__init__.py\", line 1964, in find_distributions\n",
      "    importer = get_importer(path_item)\n",
      "  File \"/home/bschroed/anaconda3/envs/pyGromosTools/lib/python3.7/pkgutil.py\", line 419, in get_importer\n",
      "    importer = path_hook(path_item)\n",
      "  File \"<frozen importlib._bootstrap_external>\", line 1447, in path_hook_for_FileFinder\n",
      "  File \"<frozen importlib._bootstrap_external>\", line 101, in _path_isdir\n",
      "FileNotFoundError: [Errno 2] No such file or directory\n",
      "\n",
      "During handling of the above exception, another exception occurred:\n",
      "\n",
      "Traceback (most recent call last):\n",
      "  File \"/home/bschroed/anaconda3/envs/pyGromosTools/lib/python3.7/site-packages/IPython/core/interactiveshell.py\", line 2061, in showtraceback\n",
      "    stb = value._render_traceback_()\n",
      "AttributeError: 'FileNotFoundError' object has no attribute '_render_traceback_'\n",
      "\n",
      "During handling of the above exception, another exception occurred:\n",
      "\n",
      "Traceback (most recent call last):\n",
      "  File \"/home/bschroed/anaconda3/envs/pyGromosTools/lib/python3.7/site-packages/IPython/core/interactiveshell.py\", line 3361, in run_ast_nodes\n",
      "    if (await self.run_code(code, result,  async_=asy)):\n",
      "  File \"/home/bschroed/anaconda3/envs/pyGromosTools/lib/python3.7/site-packages/IPython/core/interactiveshell.py\", line 3458, in run_code\n",
      "    self.showtraceback(running_compiled_code=True)\n",
      "  File \"/home/bschroed/anaconda3/envs/pyGromosTools/lib/python3.7/site-packages/IPython/core/interactiveshell.py\", line 2064, in showtraceback\n",
      "    value, tb, tb_offset=tb_offset)\n",
      "  File \"/home/bschroed/anaconda3/envs/pyGromosTools/lib/python3.7/site-packages/IPython/core/ultratb.py\", line 1368, in structured_traceback\n",
      "    self, etype, value, tb, tb_offset, number_of_lines_of_context)\n",
      "  File \"/home/bschroed/anaconda3/envs/pyGromosTools/lib/python3.7/site-packages/IPython/core/ultratb.py\", line 1268, in structured_traceback\n",
      "    self, etype, value, tb, tb_offset, number_of_lines_of_context\n",
      "  File \"/home/bschroed/anaconda3/envs/pyGromosTools/lib/python3.7/site-packages/IPython/core/ultratb.py\", line 1125, in structured_traceback\n",
      "    tb_offset)\n",
      "  File \"/home/bschroed/anaconda3/envs/pyGromosTools/lib/python3.7/site-packages/IPython/core/ultratb.py\", line 1082, in format_exception_as_a_whole\n",
      "    last_unique, recursion_repeat = find_recursion(orig_etype, evalue, records)\n",
      "  File \"/home/bschroed/anaconda3/envs/pyGromosTools/lib/python3.7/site-packages/IPython/core/ultratb.py\", line 382, in find_recursion\n",
      "    return len(records), 0\n",
      "TypeError: object of type 'NoneType' has no len()\n",
      "\n",
      "During handling of the above exception, another exception occurred:\n",
      "\n",
      "Traceback (most recent call last):\n",
      "  File \"/home/bschroed/anaconda3/envs/pyGromosTools/lib/python3.7/site-packages/IPython/core/interactiveshell.py\", line 2061, in showtraceback\n",
      "    stb = value._render_traceback_()\n",
      "AttributeError: 'TypeError' object has no attribute '_render_traceback_'\n",
      "\n",
      "During handling of the above exception, another exception occurred:\n",
      "\n",
      "Traceback (most recent call last):\n",
      "  File \"/home/bschroed/anaconda3/envs/pyGromosTools/lib/python3.7/site-packages/IPython/core/ultratb.py\", line 1101, in get_records\n",
      "    return _fixed_getinnerframes(etb, number_of_lines_of_context, tb_offset)\n",
      "  File \"/home/bschroed/anaconda3/envs/pyGromosTools/lib/python3.7/site-packages/IPython/core/ultratb.py\", line 248, in wrapped\n",
      "    return f(*args, **kwargs)\n",
      "  File \"/home/bschroed/anaconda3/envs/pyGromosTools/lib/python3.7/site-packages/IPython/core/ultratb.py\", line 281, in _fixed_getinnerframes\n",
      "    records = fix_frame_records_filenames(inspect.getinnerframes(etb, context))\n",
      "  File \"/home/bschroed/anaconda3/envs/pyGromosTools/lib/python3.7/inspect.py\", line 1502, in getinnerframes\n",
      "    frameinfo = (tb.tb_frame,) + getframeinfo(tb, context)\n",
      "  File \"/home/bschroed/anaconda3/envs/pyGromosTools/lib/python3.7/inspect.py\", line 1460, in getframeinfo\n",
      "    filename = getsourcefile(frame) or getfile(frame)\n",
      "  File \"/home/bschroed/anaconda3/envs/pyGromosTools/lib/python3.7/inspect.py\", line 696, in getsourcefile\n",
      "    if getattr(getmodule(object, filename), '__loader__', None) is not None:\n",
      "  File \"/home/bschroed/anaconda3/envs/pyGromosTools/lib/python3.7/inspect.py\", line 725, in getmodule\n",
      "    file = getabsfile(object, _filename)\n",
      "  File \"/home/bschroed/anaconda3/envs/pyGromosTools/lib/python3.7/inspect.py\", line 709, in getabsfile\n",
      "    return os.path.normcase(os.path.abspath(_filename))\n",
      "  File \"/home/bschroed/anaconda3/envs/pyGromosTools/lib/python3.7/posixpath.py\", line 383, in abspath\n",
      "    cwd = os.getcwd()\n",
      "FileNotFoundError: [Errno 2] No such file or directory\n",
      "Traceback (most recent call last):\n",
      "  File \"/home/bschroed/anaconda3/envs/pyGromosTools/lib/python3.7/pkgutil.py\", line 415, in get_importer\n",
      "    importer = sys.path_importer_cache[path_item]\n",
      "KeyError: ''\n",
      "\n",
      "During handling of the above exception, another exception occurred:\n",
      "\n",
      "Traceback (most recent call last):\n",
      "  File \"/home/bschroed/anaconda3/envs/pyGromosTools/lib/python3.7/site-packages/IPython/core/interactiveshell.py\", line 3441, in run_code\n",
      "    exec(code_obj, self.user_global_ns, self.user_ns)\n",
      "  File \"<ipython-input-12-38475b66d665>\", line 5, in <module>\n",
      "    tre = Tre(input_value=in_path)\n",
      "  File \"/home/bschroed/Documents/projects/PyGromosTools/pygromos/files/trajectory/tre.py\", line 28, in __init__\n",
      "    super().__init__(input_value, auto_save=auto_save, stride=stride, skip=skip)\n",
      "  File \"/home/bschroed/Documents/projects/PyGromosTools/pygromos/files/trajectory/_general_trajectory.py\", line 48, in __init__\n",
      "    self._read_from_file(input_path=input_value, auto_save=auto_save, stride=stride, skip=skip)\n",
      "  File \"/home/bschroed/Documents/projects/PyGromosTools/pygromos/files/trajectory/_general_trajectory.py\", line 136, in _read_from_file\n",
      "    self._read_db_from_hf5(input_path=input_path)\n",
      "  File \"/home/bschroed/Documents/projects/PyGromosTools/pygromos/files/trajectory/_general_trajectory.py\", line 144, in _read_db_from_hf5\n",
      "    self.database = pandas.read_hdf(path_or_buf=input_path, key=input_path.split(\".\")[-1])\n",
      "  File \"/home/bschroed/anaconda3/envs/pyGromosTools/lib/python3.7/site-packages/pandas/io/pytables.py\", line 399, in read_hdf\n",
      "    store = HDFStore(path_or_buf, mode=mode, errors=errors, **kwargs)\n",
      "  File \"/home/bschroed/anaconda3/envs/pyGromosTools/lib/python3.7/site-packages/pandas/io/pytables.py\", line 542, in __init__\n",
      "    tables = import_optional_dependency(\"tables\")\n",
      "  File \"/home/bschroed/anaconda3/envs/pyGromosTools/lib/python3.7/site-packages/pandas/compat/_optional.py\", line 106, in import_optional_dependency\n",
      "    module = importlib.import_module(name)\n",
      "  File \"/home/bschroed/anaconda3/envs/pyGromosTools/lib/python3.7/importlib/__init__.py\", line 127, in import_module\n",
      "    return _bootstrap._gcd_import(name[level:], package, level)\n",
      "  File \"<frozen importlib._bootstrap>\", line 1006, in _gcd_import\n",
      "  File \"<frozen importlib._bootstrap>\", line 983, in _find_and_load\n",
      "  File \"<frozen importlib._bootstrap>\", line 967, in _find_and_load_unlocked\n",
      "  File \"<frozen importlib._bootstrap>\", line 677, in _load_unlocked\n",
      "  File \"<frozen importlib._bootstrap_external>\", line 728, in exec_module\n",
      "  File \"<frozen importlib._bootstrap>\", line 219, in _call_with_frames_removed\n",
      "  File \"/home/bschroed/anaconda3/envs/pyGromosTools/lib/python3.7/site-packages/tables/__init__.py\", line 148, in <module>\n",
      "    from .tests import print_versions, test\n",
      "  File \"/home/bschroed/anaconda3/envs/pyGromosTools/lib/python3.7/site-packages/tables/tests/__init__.py\", line 21, in <module>\n",
      "    from tables.tests.common import print_versions\n",
      "  File \"/home/bschroed/anaconda3/envs/pyGromosTools/lib/python3.7/site-packages/tables/tests/common.py\", line 25, in <module>\n",
      "    from pkg_resources import resource_filename\n",
      "  File \"/home/bschroed/anaconda3/envs/pyGromosTools/lib/python3.7/site-packages/pkg_resources/__init__.py\", line 3242, in <module>\n",
      "    @_call_aside\n",
      "  File \"/home/bschroed/anaconda3/envs/pyGromosTools/lib/python3.7/site-packages/pkg_resources/__init__.py\", line 3226, in _call_aside\n",
      "    f(*args, **kwargs)\n",
      "  File \"/home/bschroed/anaconda3/envs/pyGromosTools/lib/python3.7/site-packages/pkg_resources/__init__.py\", line 3255, in _initialize_master_working_set\n",
      "    working_set = WorkingSet._build_master()\n",
      "  File \"/home/bschroed/anaconda3/envs/pyGromosTools/lib/python3.7/site-packages/pkg_resources/__init__.py\", line 559, in _build_master\n",
      "    ws = cls()\n",
      "  File \"/home/bschroed/anaconda3/envs/pyGromosTools/lib/python3.7/site-packages/pkg_resources/__init__.py\", line 552, in __init__\n",
      "    self.add_entry(entry)\n",
      "  File \"/home/bschroed/anaconda3/envs/pyGromosTools/lib/python3.7/site-packages/pkg_resources/__init__.py\", line 608, in add_entry\n",
      "    for dist in find_distributions(entry, True):\n",
      "  File \"/home/bschroed/anaconda3/envs/pyGromosTools/lib/python3.7/site-packages/pkg_resources/__init__.py\", line 1964, in find_distributions\n",
      "    importer = get_importer(path_item)\n",
      "  File \"/home/bschroed/anaconda3/envs/pyGromosTools/lib/python3.7/pkgutil.py\", line 419, in get_importer\n",
      "    importer = path_hook(path_item)\n",
      "  File \"<frozen importlib._bootstrap_external>\", line 1447, in path_hook_for_FileFinder\n",
      "  File \"<frozen importlib._bootstrap_external>\", line 101, in _path_isdir\n",
      "FileNotFoundError: [Errno 2] No such file or directory\n",
      "\n",
      "During handling of the above exception, another exception occurred:\n",
      "\n",
      "Traceback (most recent call last):\n",
      "  File \"/home/bschroed/anaconda3/envs/pyGromosTools/lib/python3.7/site-packages/IPython/core/interactiveshell.py\", line 2061, in showtraceback\n",
      "    stb = value._render_traceback_()\n",
      "AttributeError: 'FileNotFoundError' object has no attribute '_render_traceback_'\n",
      "\n",
      "During handling of the above exception, another exception occurred:\n",
      "\n",
      "Traceback (most recent call last):\n",
      "  File \"/home/bschroed/anaconda3/envs/pyGromosTools/lib/python3.7/site-packages/IPython/core/interactiveshell.py\", line 3361, in run_ast_nodes\n",
      "    if (await self.run_code(code, result,  async_=asy)):\n",
      "  File \"/home/bschroed/anaconda3/envs/pyGromosTools/lib/python3.7/site-packages/IPython/core/interactiveshell.py\", line 3458, in run_code\n",
      "    self.showtraceback(running_compiled_code=True)\n",
      "  File \"/home/bschroed/anaconda3/envs/pyGromosTools/lib/python3.7/site-packages/IPython/core/interactiveshell.py\", line 2064, in showtraceback\n",
      "    value, tb, tb_offset=tb_offset)\n",
      "  File \"/home/bschroed/anaconda3/envs/pyGromosTools/lib/python3.7/site-packages/IPython/core/ultratb.py\", line 1368, in structured_traceback\n",
      "    self, etype, value, tb, tb_offset, number_of_lines_of_context)\n",
      "  File \"/home/bschroed/anaconda3/envs/pyGromosTools/lib/python3.7/site-packages/IPython/core/ultratb.py\", line 1268, in structured_traceback\n",
      "    self, etype, value, tb, tb_offset, number_of_lines_of_context\n",
      "  File \"/home/bschroed/anaconda3/envs/pyGromosTools/lib/python3.7/site-packages/IPython/core/ultratb.py\", line 1125, in structured_traceback\n",
      "    tb_offset)\n",
      "  File \"/home/bschroed/anaconda3/envs/pyGromosTools/lib/python3.7/site-packages/IPython/core/ultratb.py\", line 1082, in format_exception_as_a_whole\n",
      "    last_unique, recursion_repeat = find_recursion(orig_etype, evalue, records)\n",
      "  File \"/home/bschroed/anaconda3/envs/pyGromosTools/lib/python3.7/site-packages/IPython/core/ultratb.py\", line 382, in find_recursion\n",
      "    return len(records), 0\n",
      "TypeError: object of type 'NoneType' has no len()\n",
      "\n",
      "During handling of the above exception, another exception occurred:\n",
      "\n",
      "Traceback (most recent call last):\n",
      "  File \"/home/bschroed/anaconda3/envs/pyGromosTools/lib/python3.7/site-packages/IPython/core/interactiveshell.py\", line 2061, in showtraceback\n",
      "    stb = value._render_traceback_()\n",
      "AttributeError: 'TypeError' object has no attribute '_render_traceback_'\n",
      "\n",
      "During handling of the above exception, another exception occurred:\n",
      "\n",
      "Traceback (most recent call last):\n",
      "  File \"/home/bschroed/anaconda3/envs/pyGromosTools/lib/python3.7/site-packages/IPython/core/interactiveshell.py\", line 2944, in _run_cell\n",
      "    return runner(coro)\n",
      "  File \"/home/bschroed/anaconda3/envs/pyGromosTools/lib/python3.7/site-packages/IPython/core/async_helpers.py\", line 68, in _pseudo_sync_runner\n",
      "    coro.send(None)\n",
      "  File \"/home/bschroed/anaconda3/envs/pyGromosTools/lib/python3.7/site-packages/IPython/core/interactiveshell.py\", line 3170, in run_cell_async\n",
      "    interactivity=interactivity, compiler=compiler, result=result)\n",
      "  File \"/home/bschroed/anaconda3/envs/pyGromosTools/lib/python3.7/site-packages/IPython/core/interactiveshell.py\", line 3380, in run_ast_nodes\n",
      "    self.showtraceback()\n",
      "  File \"/home/bschroed/anaconda3/envs/pyGromosTools/lib/python3.7/site-packages/IPython/core/interactiveshell.py\", line 2064, in showtraceback\n",
      "    value, tb, tb_offset=tb_offset)\n",
      "  File \"/home/bschroed/anaconda3/envs/pyGromosTools/lib/python3.7/site-packages/IPython/core/ultratb.py\", line 1368, in structured_traceback\n",
      "    self, etype, value, tb, tb_offset, number_of_lines_of_context)\n",
      "  File \"/home/bschroed/anaconda3/envs/pyGromosTools/lib/python3.7/site-packages/IPython/core/ultratb.py\", line 1268, in structured_traceback\n",
      "    self, etype, value, tb, tb_offset, number_of_lines_of_context\n",
      "  File \"/home/bschroed/anaconda3/envs/pyGromosTools/lib/python3.7/site-packages/IPython/core/ultratb.py\", line 1143, in structured_traceback\n",
      "    chained_exceptions_tb_offset)\n",
      "  File \"/home/bschroed/anaconda3/envs/pyGromosTools/lib/python3.7/site-packages/IPython/core/ultratb.py\", line 1082, in format_exception_as_a_whole\n",
      "    last_unique, recursion_repeat = find_recursion(orig_etype, evalue, records)\n",
      "  File \"/home/bschroed/anaconda3/envs/pyGromosTools/lib/python3.7/site-packages/IPython/core/ultratb.py\", line 382, in find_recursion\n",
      "    return len(records), 0\n",
      "TypeError: object of type 'NoneType' has no len()\n",
      "\n",
      "During handling of the above exception, another exception occurred:\n",
      "\n",
      "Traceback (most recent call last):\n",
      "  File \"/home/bschroed/anaconda3/envs/pyGromosTools/lib/python3.7/site-packages/IPython/core/interactiveshell.py\", line 2061, in showtraceback\n",
      "    stb = value._render_traceback_()\n",
      "AttributeError: 'TypeError' object has no attribute '_render_traceback_'\n",
      "\n",
      "During handling of the above exception, another exception occurred:\n",
      "\n",
      "Traceback (most recent call last):\n",
      "  File \"/home/bschroed/anaconda3/envs/pyGromosTools/lib/python3.7/site-packages/IPython/core/ultratb.py\", line 1101, in get_records\n",
      "    return _fixed_getinnerframes(etb, number_of_lines_of_context, tb_offset)\n",
      "  File \"/home/bschroed/anaconda3/envs/pyGromosTools/lib/python3.7/site-packages/IPython/core/ultratb.py\", line 248, in wrapped\n",
      "    return f(*args, **kwargs)\n",
      "  File \"/home/bschroed/anaconda3/envs/pyGromosTools/lib/python3.7/site-packages/IPython/core/ultratb.py\", line 281, in _fixed_getinnerframes\n",
      "    records = fix_frame_records_filenames(inspect.getinnerframes(etb, context))\n",
      "  File \"/home/bschroed/anaconda3/envs/pyGromosTools/lib/python3.7/inspect.py\", line 1502, in getinnerframes\n",
      "    frameinfo = (tb.tb_frame,) + getframeinfo(tb, context)\n",
      "  File \"/home/bschroed/anaconda3/envs/pyGromosTools/lib/python3.7/inspect.py\", line 1460, in getframeinfo\n",
      "    filename = getsourcefile(frame) or getfile(frame)\n",
      "  File \"/home/bschroed/anaconda3/envs/pyGromosTools/lib/python3.7/inspect.py\", line 696, in getsourcefile\n",
      "    if getattr(getmodule(object, filename), '__loader__', None) is not None:\n",
      "  File \"/home/bschroed/anaconda3/envs/pyGromosTools/lib/python3.7/inspect.py\", line 725, in getmodule\n",
      "    file = getabsfile(object, _filename)\n",
      "  File \"/home/bschroed/anaconda3/envs/pyGromosTools/lib/python3.7/inspect.py\", line 709, in getabsfile\n",
      "    return os.path.normcase(os.path.abspath(_filename))\n",
      "  File \"/home/bschroed/anaconda3/envs/pyGromosTools/lib/python3.7/posixpath.py\", line 383, in abspath\n",
      "    cwd = os.getcwd()\n",
      "FileNotFoundError: [Errno 2] No such file or directory\n"
     ]
    }
   ],
   "source": [
    "from pygromos.files.trajectory.tre import Tre\n",
    "\n",
    "in_path=project_dir+\"/b_vacuum_sd/analysis/data/b_vacuum_sd.tre.h5\"\n",
    "\n",
    "tre = Tre(input_value=in_path)\n",
    "tre\n",
    "\n"
   ]
  },
  {
   "cell_type": "code",
   "execution_count": null,
   "metadata": {
    "pycharm": {
     "name": "#%%\n"
    }
   },
   "outputs": [
    {
     "name": "stderr",
     "output_type": "stream",
     "text": [
      "ERROR:root:Internal Python error in the inspect module.\n",
      "Below is the traceback from this internal error.\n",
      "\n"
     ]
    },
    {
     "name": "stdout",
     "output_type": "stream",
     "text": [
      "Traceback (most recent call last):\n",
      "  File \"/home/bschroed/anaconda3/envs/pyGromosTools/lib/python3.7/site-packages/IPython/core/interactiveshell.py\", line 3441, in run_code\n",
      "    exec(code_obj, self.user_global_ns, self.user_ns)\n",
      "  File \"<ipython-input-12-a2854131c25f>\", line 2, in <module>\n",
      "    V_tot = np.array(list(map(lambda x: x[2], tre.database.totals)))\n",
      "NameError: name 'tre' is not defined\n",
      "\n",
      "During handling of the above exception, another exception occurred:\n",
      "\n",
      "Traceback (most recent call last):\n",
      "  File \"/home/bschroed/anaconda3/envs/pyGromosTools/lib/python3.7/site-packages/IPython/core/interactiveshell.py\", line 2061, in showtraceback\n",
      "    stb = value._render_traceback_()\n",
      "AttributeError: 'NameError' object has no attribute '_render_traceback_'\n",
      "\n",
      "During handling of the above exception, another exception occurred:\n",
      "\n",
      "Traceback (most recent call last):\n",
      "  File \"/home/bschroed/anaconda3/envs/pyGromosTools/lib/python3.7/site-packages/IPython/core/ultratb.py\", line 1101, in get_records\n",
      "    return _fixed_getinnerframes(etb, number_of_lines_of_context, tb_offset)\n",
      "  File \"/home/bschroed/anaconda3/envs/pyGromosTools/lib/python3.7/site-packages/IPython/core/ultratb.py\", line 248, in wrapped\n",
      "    return f(*args, **kwargs)\n",
      "  File \"/home/bschroed/anaconda3/envs/pyGromosTools/lib/python3.7/site-packages/IPython/core/ultratb.py\", line 281, in _fixed_getinnerframes\n",
      "    records = fix_frame_records_filenames(inspect.getinnerframes(etb, context))\n",
      "  File \"/home/bschroed/anaconda3/envs/pyGromosTools/lib/python3.7/inspect.py\", line 1502, in getinnerframes\n",
      "    frameinfo = (tb.tb_frame,) + getframeinfo(tb, context)\n",
      "  File \"/home/bschroed/anaconda3/envs/pyGromosTools/lib/python3.7/inspect.py\", line 1460, in getframeinfo\n",
      "    filename = getsourcefile(frame) or getfile(frame)\n",
      "  File \"/home/bschroed/anaconda3/envs/pyGromosTools/lib/python3.7/inspect.py\", line 696, in getsourcefile\n",
      "    if getattr(getmodule(object, filename), '__loader__', None) is not None:\n",
      "  File \"/home/bschroed/anaconda3/envs/pyGromosTools/lib/python3.7/inspect.py\", line 725, in getmodule\n",
      "    file = getabsfile(object, _filename)\n",
      "  File \"/home/bschroed/anaconda3/envs/pyGromosTools/lib/python3.7/inspect.py\", line 709, in getabsfile\n",
      "    return os.path.normcase(os.path.abspath(_filename))\n",
      "  File \"/home/bschroed/anaconda3/envs/pyGromosTools/lib/python3.7/posixpath.py\", line 383, in abspath\n",
      "    cwd = os.getcwd()\n",
      "FileNotFoundError: [Errno 2] No such file or directory\n"
     ]
    },
    {
     "name": "stderr",
     "output_type": "stream",
     "text": [
      "ERROR:root:Internal Python error in the inspect module.\n",
      "Below is the traceback from this internal error.\n",
      "\n",
      "ERROR:root:Internal Python error in the inspect module.\n",
      "Below is the traceback from this internal error.\n",
      "\n"
     ]
    },
    {
     "name": "stdout",
     "output_type": "stream",
     "text": [
      "ERROR! Session/line number was not unique in database. History logging moved to new session Traceback (most recent call last):\n",
      "  File \"/home/bschroed/anaconda3/envs/pyGromosTools/lib/python3.7/site-packages/IPython/core/interactiveshell.py\", line 3441, in run_code\n",
      "    exec(code_obj, self.user_global_ns, self.user_ns)\n",
      "  File \"<ipython-input-12-a2854131c25f>\", line 2, in <module>\n",
      "    V_tot = np.array(list(map(lambda x: x[2], tre.database.totals)))\n",
      "NameError: name 'tre' is not defined\n",
      "\n",
      "During handling of the above exception, another exception occurred:\n",
      "\n",
      "Traceback (most recent call last):\n",
      "  File \"/home/bschroed/anaconda3/envs/pyGromosTools/lib/python3.7/site-packages/IPython/core/interactiveshell.py\", line 2061, in showtraceback\n",
      "    stb = value._render_traceback_()\n",
      "AttributeError: 'NameError' object has no attribute '_render_traceback_'\n",
      "\n",
      "During handling of the above exception, another exception occurred:\n",
      "\n",
      "Traceback (most recent call last):\n",
      "  File \"/home/bschroed/anaconda3/envs/pyGromosTools/lib/python3.7/site-packages/IPython/core/interactiveshell.py\", line 3361, in run_ast_nodes\n",
      "    if (await self.run_code(code, result,  async_=asy)):\n",
      "  File \"/home/bschroed/anaconda3/envs/pyGromosTools/lib/python3.7/site-packages/IPython/core/interactiveshell.py\", line 3458, in run_code\n",
      "    self.showtraceback(running_compiled_code=True)\n",
      "  File \"/home/bschroed/anaconda3/envs/pyGromosTools/lib/python3.7/site-packages/IPython/core/interactiveshell.py\", line 2064, in showtraceback\n",
      "    value, tb, tb_offset=tb_offset)\n",
      "  File \"/home/bschroed/anaconda3/envs/pyGromosTools/lib/python3.7/site-packages/IPython/core/ultratb.py\", line 1368, in structured_traceback\n",
      "    self, etype, value, tb, tb_offset, number_of_lines_of_context)\n",
      "  File \"/home/bschroed/anaconda3/envs/pyGromosTools/lib/python3.7/site-packages/IPython/core/ultratb.py\", line 1268, in structured_traceback\n",
      "    self, etype, value, tb, tb_offset, number_of_lines_of_context\n",
      "  File \"/home/bschroed/anaconda3/envs/pyGromosTools/lib/python3.7/site-packages/IPython/core/ultratb.py\", line 1125, in structured_traceback\n",
      "    tb_offset)\n",
      "  File \"/home/bschroed/anaconda3/envs/pyGromosTools/lib/python3.7/site-packages/IPython/core/ultratb.py\", line 1082, in format_exception_as_a_whole\n",
      "    last_unique, recursion_repeat = find_recursion(orig_etype, evalue, records)\n",
      "  File \"/home/bschroed/anaconda3/envs/pyGromosTools/lib/python3.7/site-packages/IPython/core/ultratb.py\", line 382, in find_recursion\n",
      "    return len(records), 0\n",
      "TypeError: object of type 'NoneType' has no len()\n",
      "\n",
      "During handling of the above exception, another exception occurred:\n",
      "\n",
      "Traceback (most recent call last):\n",
      "  File \"/home/bschroed/anaconda3/envs/pyGromosTools/lib/python3.7/site-packages/IPython/core/interactiveshell.py\", line 2061, in showtraceback\n",
      "    stb = value._render_traceback_()\n",
      "AttributeError: 'TypeError' object has no attribute '_render_traceback_'\n",
      "\n",
      "During handling of the above exception, another exception occurred:\n",
      "\n",
      "Traceback (most recent call last):\n",
      "  File \"/home/bschroed/anaconda3/envs/pyGromosTools/lib/python3.7/site-packages/IPython/core/ultratb.py\", line 1101, in get_records\n",
      "    return _fixed_getinnerframes(etb, number_of_lines_of_context, tb_offset)\n",
      "  File \"/home/bschroed/anaconda3/envs/pyGromosTools/lib/python3.7/site-packages/IPython/core/ultratb.py\", line 248, in wrapped\n",
      "    return f(*args, **kwargs)\n",
      "  File \"/home/bschroed/anaconda3/envs/pyGromosTools/lib/python3.7/site-packages/IPython/core/ultratb.py\", line 281, in _fixed_getinnerframes\n",
      "    records = fix_frame_records_filenames(inspect.getinnerframes(etb, context))\n",
      "  File \"/home/bschroed/anaconda3/envs/pyGromosTools/lib/python3.7/inspect.py\", line 1502, in getinnerframes\n",
      "    frameinfo = (tb.tb_frame,) + getframeinfo(tb, context)\n",
      "  File \"/home/bschroed/anaconda3/envs/pyGromosTools/lib/python3.7/inspect.py\", line 1460, in getframeinfo\n",
      "    filename = getsourcefile(frame) or getfile(frame)\n",
      "  File \"/home/bschroed/anaconda3/envs/pyGromosTools/lib/python3.7/inspect.py\", line 696, in getsourcefile\n",
      "    if getattr(getmodule(object, filename), '__loader__', None) is not None:\n",
      "  File \"/home/bschroed/anaconda3/envs/pyGromosTools/lib/python3.7/inspect.py\", line 725, in getmodule\n",
      "    file = getabsfile(object, _filename)\n",
      "  File \"/home/bschroed/anaconda3/envs/pyGromosTools/lib/python3.7/inspect.py\", line 709, in getabsfile\n",
      "    return os.path.normcase(os.path.abspath(_filename))\n",
      "  File \"/home/bschroed/anaconda3/envs/pyGromosTools/lib/python3.7/posixpath.py\", line 383, in abspath\n",
      "    cwd = os.getcwd()\n",
      "FileNotFoundError: [Errno 2] No such file or directory\n",
      "172\n",
      "Traceback (most recent call last):\n",
      "  File \"/home/bschroed/anaconda3/envs/pyGromosTools/lib/python3.7/site-packages/IPython/core/interactiveshell.py\", line 3441, in run_code\n",
      "    exec(code_obj, self.user_global_ns, self.user_ns)\n",
      "  File \"<ipython-input-12-a2854131c25f>\", line 2, in <module>\n",
      "    V_tot = np.array(list(map(lambda x: x[2], tre.database.totals)))\n",
      "NameError: name 'tre' is not defined\n",
      "\n",
      "During handling of the above exception, another exception occurred:\n",
      "\n",
      "Traceback (most recent call last):\n",
      "  File \"/home/bschroed/anaconda3/envs/pyGromosTools/lib/python3.7/site-packages/IPython/core/interactiveshell.py\", line 2061, in showtraceback\n",
      "    stb = value._render_traceback_()\n",
      "AttributeError: 'NameError' object has no attribute '_render_traceback_'\n",
      "\n",
      "During handling of the above exception, another exception occurred:\n",
      "\n",
      "Traceback (most recent call last):\n",
      "  File \"/home/bschroed/anaconda3/envs/pyGromosTools/lib/python3.7/site-packages/IPython/core/interactiveshell.py\", line 3361, in run_ast_nodes\n",
      "    if (await self.run_code(code, result,  async_=asy)):\n",
      "  File \"/home/bschroed/anaconda3/envs/pyGromosTools/lib/python3.7/site-packages/IPython/core/interactiveshell.py\", line 3458, in run_code\n",
      "    self.showtraceback(running_compiled_code=True)\n",
      "  File \"/home/bschroed/anaconda3/envs/pyGromosTools/lib/python3.7/site-packages/IPython/core/interactiveshell.py\", line 2064, in showtraceback\n",
      "    value, tb, tb_offset=tb_offset)\n",
      "  File \"/home/bschroed/anaconda3/envs/pyGromosTools/lib/python3.7/site-packages/IPython/core/ultratb.py\", line 1368, in structured_traceback\n",
      "    self, etype, value, tb, tb_offset, number_of_lines_of_context)\n",
      "  File \"/home/bschroed/anaconda3/envs/pyGromosTools/lib/python3.7/site-packages/IPython/core/ultratb.py\", line 1268, in structured_traceback\n",
      "    self, etype, value, tb, tb_offset, number_of_lines_of_context\n",
      "  File \"/home/bschroed/anaconda3/envs/pyGromosTools/lib/python3.7/site-packages/IPython/core/ultratb.py\", line 1125, in structured_traceback\n",
      "    tb_offset)\n",
      "  File \"/home/bschroed/anaconda3/envs/pyGromosTools/lib/python3.7/site-packages/IPython/core/ultratb.py\", line 1082, in format_exception_as_a_whole\n",
      "    last_unique, recursion_repeat = find_recursion(orig_etype, evalue, records)\n",
      "  File \"/home/bschroed/anaconda3/envs/pyGromosTools/lib/python3.7/site-packages/IPython/core/ultratb.py\", line 382, in find_recursion\n",
      "    return len(records), 0\n",
      "TypeError: object of type 'NoneType' has no len()\n",
      "\n",
      "During handling of the above exception, another exception occurred:\n",
      "\n",
      "Traceback (most recent call last):\n",
      "  File \"/home/bschroed/anaconda3/envs/pyGromosTools/lib/python3.7/site-packages/IPython/core/interactiveshell.py\", line 2061, in showtraceback\n",
      "    stb = value._render_traceback_()\n",
      "AttributeError: 'TypeError' object has no attribute '_render_traceback_'\n",
      "\n",
      "During handling of the above exception, another exception occurred:\n",
      "\n",
      "Traceback (most recent call last):\n",
      "  File \"/home/bschroed/anaconda3/envs/pyGromosTools/lib/python3.7/site-packages/IPython/core/interactiveshell.py\", line 2944, in _run_cell\n",
      "    return runner(coro)\n",
      "  File \"/home/bschroed/anaconda3/envs/pyGromosTools/lib/python3.7/site-packages/IPython/core/async_helpers.py\", line 68, in _pseudo_sync_runner\n",
      "    coro.send(None)\n",
      "  File \"/home/bschroed/anaconda3/envs/pyGromosTools/lib/python3.7/site-packages/IPython/core/interactiveshell.py\", line 3170, in run_cell_async\n",
      "    interactivity=interactivity, compiler=compiler, result=result)\n",
      "  File \"/home/bschroed/anaconda3/envs/pyGromosTools/lib/python3.7/site-packages/IPython/core/interactiveshell.py\", line 3380, in run_ast_nodes\n",
      "    self.showtraceback()\n",
      "  File \"/home/bschroed/anaconda3/envs/pyGromosTools/lib/python3.7/site-packages/IPython/core/interactiveshell.py\", line 2064, in showtraceback\n",
      "    value, tb, tb_offset=tb_offset)\n",
      "  File \"/home/bschroed/anaconda3/envs/pyGromosTools/lib/python3.7/site-packages/IPython/core/ultratb.py\", line 1368, in structured_traceback\n",
      "    self, etype, value, tb, tb_offset, number_of_lines_of_context)\n",
      "  File \"/home/bschroed/anaconda3/envs/pyGromosTools/lib/python3.7/site-packages/IPython/core/ultratb.py\", line 1268, in structured_traceback\n",
      "    self, etype, value, tb, tb_offset, number_of_lines_of_context\n",
      "  File \"/home/bschroed/anaconda3/envs/pyGromosTools/lib/python3.7/site-packages/IPython/core/ultratb.py\", line 1143, in structured_traceback\n",
      "    chained_exceptions_tb_offset)\n",
      "  File \"/home/bschroed/anaconda3/envs/pyGromosTools/lib/python3.7/site-packages/IPython/core/ultratb.py\", line 1082, in format_exception_as_a_whole\n",
      "    last_unique, recursion_repeat = find_recursion(orig_etype, evalue, records)\n",
      "  File \"/home/bschroed/anaconda3/envs/pyGromosTools/lib/python3.7/site-packages/IPython/core/ultratb.py\", line 382, in find_recursion\n",
      "    return len(records), 0\n",
      "TypeError: object of type 'NoneType' has no len()\n",
      "\n",
      "During handling of the above exception, another exception occurred:\n",
      "\n",
      "Traceback (most recent call last):\n",
      "  File \"/home/bschroed/anaconda3/envs/pyGromosTools/lib/python3.7/site-packages/IPython/core/interactiveshell.py\", line 2061, in showtraceback\n",
      "    stb = value._render_traceback_()\n",
      "AttributeError: 'TypeError' object has no attribute '_render_traceback_'\n",
      "\n",
      "During handling of the above exception, another exception occurred:\n",
      "\n",
      "Traceback (most recent call last):\n",
      "  File \"/home/bschroed/anaconda3/envs/pyGromosTools/lib/python3.7/site-packages/IPython/core/ultratb.py\", line 1101, in get_records\n",
      "    return _fixed_getinnerframes(etb, number_of_lines_of_context, tb_offset)\n",
      "  File \"/home/bschroed/anaconda3/envs/pyGromosTools/lib/python3.7/site-packages/IPython/core/ultratb.py\", line 248, in wrapped\n",
      "    return f(*args, **kwargs)\n",
      "  File \"/home/bschroed/anaconda3/envs/pyGromosTools/lib/python3.7/site-packages/IPython/core/ultratb.py\", line 281, in _fixed_getinnerframes\n",
      "    records = fix_frame_records_filenames(inspect.getinnerframes(etb, context))\n",
      "  File \"/home/bschroed/anaconda3/envs/pyGromosTools/lib/python3.7/inspect.py\", line 1502, in getinnerframes\n",
      "    frameinfo = (tb.tb_frame,) + getframeinfo(tb, context)\n",
      "  File \"/home/bschroed/anaconda3/envs/pyGromosTools/lib/python3.7/inspect.py\", line 1460, in getframeinfo\n",
      "    filename = getsourcefile(frame) or getfile(frame)\n",
      "  File \"/home/bschroed/anaconda3/envs/pyGromosTools/lib/python3.7/inspect.py\", line 696, in getsourcefile\n",
      "    if getattr(getmodule(object, filename), '__loader__', None) is not None:\n",
      "  File \"/home/bschroed/anaconda3/envs/pyGromosTools/lib/python3.7/inspect.py\", line 725, in getmodule\n",
      "    file = getabsfile(object, _filename)\n",
      "  File \"/home/bschroed/anaconda3/envs/pyGromosTools/lib/python3.7/inspect.py\", line 709, in getabsfile\n",
      "    return os.path.normcase(os.path.abspath(_filename))\n",
      "  File \"/home/bschroed/anaconda3/envs/pyGromosTools/lib/python3.7/posixpath.py\", line 383, in abspath\n",
      "    cwd = os.getcwd()\n",
      "FileNotFoundError: [Errno 2] No such file or directory\n"
     ]
    }
   ],
   "source": [
    "#Plot Potential Energies\n",
    "V_tot = np.array(list(map(lambda x: x[2], tre.database.totals)))\n",
    "step = len(tre.database.TIMESTEP_time)//10\n",
    "\n",
    "plt.plot(tre.database.TIMESTEP_time, V_tot)\n",
    "plt.xticks(np.round(list(tre.database.TIMESTEP_time[::step]),2))\n",
    "plt.xlabel(\"$t~[ps]$\")\n",
    "plt.ylabel(\"$V~[kJ]$\")\n",
    "plt.title(\"V total timeseries\")\n",
    "plt.savefig(out_ana+\"/potential_energy_timeseries.png\")\n",
    "\n"
   ]
  },
  {
   "cell_type": "markdown",
   "metadata": {},
   "source": [
    "## Lambda Sampling\n",
    "\n",
    "### Setup again"
   ]
  },
  {
   "cell_type": "code",
   "execution_count": null,
   "metadata": {
    "pycharm": {
     "name": "#%%\n"
    }
   },
   "outputs": [
    {
     "name": "stderr",
     "output_type": "stream",
     "text": [
      "ERROR:root:Internal Python error in the inspect module.\n",
      "Below is the traceback from this internal error.\n",
      "\n",
      "ERROR:root:Internal Python error in the inspect module.\n",
      "Below is the traceback from this internal error.\n",
      "\n"
     ]
    },
    {
     "name": "stdout",
     "output_type": "stream",
     "text": [
      "Traceback (most recent call last):\n",
      "  File \"/home/bschroed/anaconda3/envs/pyGromosTools/lib/python3.7/site-packages/IPython/core/interactiveshell.py\", line 3441, in run_code\n",
      "    exec(code_obj, self.user_global_ns, self.user_ns)\n",
      "  File \"<ipython-input-12-d254c08af3d9>\", line 8, in <module>\n",
      "    root_dir = os.getcwd()+\"/example_files/TI_Calculation\"\n",
      "FileNotFoundError: [Errno 2] No such file or directory\n",
      "\n",
      "During handling of the above exception, another exception occurred:\n",
      "\n",
      "Traceback (most recent call last):\n",
      "  File \"/home/bschroed/anaconda3/envs/pyGromosTools/lib/python3.7/site-packages/IPython/core/interactiveshell.py\", line 2061, in showtraceback\n",
      "    stb = value._render_traceback_()\n",
      "AttributeError: 'FileNotFoundError' object has no attribute '_render_traceback_'\n",
      "\n",
      "During handling of the above exception, another exception occurred:\n",
      "\n",
      "Traceback (most recent call last):\n",
      "  File \"/home/bschroed/anaconda3/envs/pyGromosTools/lib/python3.7/site-packages/IPython/core/ultratb.py\", line 1101, in get_records\n",
      "    return _fixed_getinnerframes(etb, number_of_lines_of_context, tb_offset)\n",
      "  File \"/home/bschroed/anaconda3/envs/pyGromosTools/lib/python3.7/site-packages/IPython/core/ultratb.py\", line 248, in wrapped\n",
      "    return f(*args, **kwargs)\n",
      "  File \"/home/bschroed/anaconda3/envs/pyGromosTools/lib/python3.7/site-packages/IPython/core/ultratb.py\", line 281, in _fixed_getinnerframes\n",
      "    records = fix_frame_records_filenames(inspect.getinnerframes(etb, context))\n",
      "  File \"/home/bschroed/anaconda3/envs/pyGromosTools/lib/python3.7/inspect.py\", line 1502, in getinnerframes\n",
      "    frameinfo = (tb.tb_frame,) + getframeinfo(tb, context)\n",
      "  File \"/home/bschroed/anaconda3/envs/pyGromosTools/lib/python3.7/inspect.py\", line 1460, in getframeinfo\n",
      "    filename = getsourcefile(frame) or getfile(frame)\n",
      "  File \"/home/bschroed/anaconda3/envs/pyGromosTools/lib/python3.7/inspect.py\", line 696, in getsourcefile\n",
      "    if getattr(getmodule(object, filename), '__loader__', None) is not None:\n",
      "  File \"/home/bschroed/anaconda3/envs/pyGromosTools/lib/python3.7/inspect.py\", line 725, in getmodule\n",
      "    file = getabsfile(object, _filename)\n",
      "  File \"/home/bschroed/anaconda3/envs/pyGromosTools/lib/python3.7/inspect.py\", line 709, in getabsfile\n",
      "    return os.path.normcase(os.path.abspath(_filename))\n",
      "  File \"/home/bschroed/anaconda3/envs/pyGromosTools/lib/python3.7/posixpath.py\", line 383, in abspath\n",
      "    cwd = os.getcwd()\n",
      "FileNotFoundError: [Errno 2] No such file or directory\n",
      "ERROR! Session/line number was not unique in database. History logging moved to new session 173\n",
      "Traceback (most recent call last):\n",
      "  File \"/home/bschroed/anaconda3/envs/pyGromosTools/lib/python3.7/site-packages/IPython/core/interactiveshell.py\", line 3441, in run_code\n",
      "    exec(code_obj, self.user_global_ns, self.user_ns)\n",
      "  File \"<ipython-input-12-d254c08af3d9>\", line 8, in <module>\n",
      "    root_dir = os.getcwd()+\"/example_files/TI_Calculation\"\n",
      "FileNotFoundError: [Errno 2] No such file or directory\n",
      "\n",
      "During handling of the above exception, another exception occurred:\n",
      "\n",
      "Traceback (most recent call last):\n",
      "  File \"/home/bschroed/anaconda3/envs/pyGromosTools/lib/python3.7/site-packages/IPython/core/interactiveshell.py\", line 2061, in showtraceback\n",
      "    stb = value._render_traceback_()\n",
      "AttributeError: 'FileNotFoundError' object has no attribute '_render_traceback_'\n",
      "\n",
      "During handling of the above exception, another exception occurred:\n",
      "\n",
      "Traceback (most recent call last):\n",
      "  File \"/home/bschroed/anaconda3/envs/pyGromosTools/lib/python3.7/site-packages/IPython/core/interactiveshell.py\", line 3361, in run_ast_nodes\n",
      "    if (await self.run_code(code, result,  async_=asy)):\n",
      "  File \"/home/bschroed/anaconda3/envs/pyGromosTools/lib/python3.7/site-packages/IPython/core/interactiveshell.py\", line 3458, in run_code\n",
      "    self.showtraceback(running_compiled_code=True)\n",
      "  File \"/home/bschroed/anaconda3/envs/pyGromosTools/lib/python3.7/site-packages/IPython/core/interactiveshell.py\", line 2064, in showtraceback\n",
      "    value, tb, tb_offset=tb_offset)\n",
      "  File \"/home/bschroed/anaconda3/envs/pyGromosTools/lib/python3.7/site-packages/IPython/core/ultratb.py\", line 1368, in structured_traceback\n",
      "    self, etype, value, tb, tb_offset, number_of_lines_of_context)\n"
     ]
    },
    {
     "name": "stderr",
     "output_type": "stream",
     "text": [
      "ERROR:root:Internal Python error in the inspect module.\n",
      "Below is the traceback from this internal error.\n",
      "\n"
     ]
    },
    {
     "name": "stdout",
     "output_type": "stream",
     "text": [
      "  File \"/home/bschroed/anaconda3/envs/pyGromosTools/lib/python3.7/site-packages/IPython/core/ultratb.py\", line 1268, in structured_traceback\n",
      "    self, etype, value, tb, tb_offset, number_of_lines_of_context\n",
      "  File \"/home/bschroed/anaconda3/envs/pyGromosTools/lib/python3.7/site-packages/IPython/core/ultratb.py\", line 1125, in structured_traceback\n",
      "    tb_offset)\n",
      "  File \"/home/bschroed/anaconda3/envs/pyGromosTools/lib/python3.7/site-packages/IPython/core/ultratb.py\", line 1082, in format_exception_as_a_whole\n",
      "    last_unique, recursion_repeat = find_recursion(orig_etype, evalue, records)\n",
      "  File \"/home/bschroed/anaconda3/envs/pyGromosTools/lib/python3.7/site-packages/IPython/core/ultratb.py\", line 382, in find_recursion\n",
      "    return len(records), 0\n",
      "TypeError: object of type 'NoneType' has no len()\n",
      "\n",
      "During handling of the above exception, another exception occurred:\n",
      "\n",
      "Traceback (most recent call last):\n",
      "  File \"/home/bschroed/anaconda3/envs/pyGromosTools/lib/python3.7/site-packages/IPython/core/interactiveshell.py\", line 2061, in showtraceback\n",
      "    stb = value._render_traceback_()\n",
      "AttributeError: 'TypeError' object has no attribute '_render_traceback_'\n",
      "\n",
      "During handling of the above exception, another exception occurred:\n",
      "\n",
      "Traceback (most recent call last):\n",
      "  File \"/home/bschroed/anaconda3/envs/pyGromosTools/lib/python3.7/site-packages/IPython/core/ultratb.py\", line 1101, in get_records\n",
      "    return _fixed_getinnerframes(etb, number_of_lines_of_context, tb_offset)\n",
      "  File \"/home/bschroed/anaconda3/envs/pyGromosTools/lib/python3.7/site-packages/IPython/core/ultratb.py\", line 248, in wrapped\n",
      "    return f(*args, **kwargs)\n",
      "  File \"/home/bschroed/anaconda3/envs/pyGromosTools/lib/python3.7/site-packages/IPython/core/ultratb.py\", line 281, in _fixed_getinnerframes\n",
      "    records = fix_frame_records_filenames(inspect.getinnerframes(etb, context))\n",
      "  File \"/home/bschroed/anaconda3/envs/pyGromosTools/lib/python3.7/inspect.py\", line 1502, in getinnerframes\n",
      "    frameinfo = (tb.tb_frame,) + getframeinfo(tb, context)\n",
      "  File \"/home/bschroed/anaconda3/envs/pyGromosTools/lib/python3.7/inspect.py\", line 1460, in getframeinfo\n",
      "    filename = getsourcefile(frame) or getfile(frame)\n",
      "  File \"/home/bschroed/anaconda3/envs/pyGromosTools/lib/python3.7/inspect.py\", line 696, in getsourcefile\n",
      "    if getattr(getmodule(object, filename), '__loader__', None) is not None:\n",
      "  File \"/home/bschroed/anaconda3/envs/pyGromosTools/lib/python3.7/inspect.py\", line 725, in getmodule\n",
      "    file = getabsfile(object, _filename)\n",
      "  File \"/home/bschroed/anaconda3/envs/pyGromosTools/lib/python3.7/inspect.py\", line 709, in getabsfile\n",
      "    return os.path.normcase(os.path.abspath(_filename))\n",
      "  File \"/home/bschroed/anaconda3/envs/pyGromosTools/lib/python3.7/posixpath.py\", line 383, in abspath\n",
      "    cwd = os.getcwd()\n",
      "FileNotFoundError: [Errno 2] No such file or directory\n",
      "Traceback (most recent call last):\n",
      "  File \"/home/bschroed/anaconda3/envs/pyGromosTools/lib/python3.7/site-packages/IPython/core/interactiveshell.py\", line 3441, in run_code\n",
      "    exec(code_obj, self.user_global_ns, self.user_ns)\n",
      "  File \"<ipython-input-12-d254c08af3d9>\", line 8, in <module>\n",
      "    root_dir = os.getcwd()+\"/example_files/TI_Calculation\"\n",
      "FileNotFoundError: [Errno 2] No such file or directory\n",
      "\n",
      "During handling of the above exception, another exception occurred:\n",
      "\n",
      "Traceback (most recent call last):\n",
      "  File \"/home/bschroed/anaconda3/envs/pyGromosTools/lib/python3.7/site-packages/IPython/core/interactiveshell.py\", line 2061, in showtraceback\n",
      "    stb = value._render_traceback_()\n",
      "AttributeError: 'FileNotFoundError' object has no attribute '_render_traceback_'\n",
      "\n",
      "During handling of the above exception, another exception occurred:\n",
      "\n",
      "Traceback (most recent call last):\n",
      "  File \"/home/bschroed/anaconda3/envs/pyGromosTools/lib/python3.7/site-packages/IPython/core/interactiveshell.py\", line 3361, in run_ast_nodes\n",
      "    if (await self.run_code(code, result,  async_=asy)):\n",
      "  File \"/home/bschroed/anaconda3/envs/pyGromosTools/lib/python3.7/site-packages/IPython/core/interactiveshell.py\", line 3458, in run_code\n",
      "    self.showtraceback(running_compiled_code=True)\n",
      "  File \"/home/bschroed/anaconda3/envs/pyGromosTools/lib/python3.7/site-packages/IPython/core/interactiveshell.py\", line 2064, in showtraceback\n",
      "    value, tb, tb_offset=tb_offset)\n",
      "  File \"/home/bschroed/anaconda3/envs/pyGromosTools/lib/python3.7/site-packages/IPython/core/ultratb.py\", line 1368, in structured_traceback\n",
      "    self, etype, value, tb, tb_offset, number_of_lines_of_context)\n",
      "  File \"/home/bschroed/anaconda3/envs/pyGromosTools/lib/python3.7/site-packages/IPython/core/ultratb.py\", line 1268, in structured_traceback\n",
      "    self, etype, value, tb, tb_offset, number_of_lines_of_context\n",
      "  File \"/home/bschroed/anaconda3/envs/pyGromosTools/lib/python3.7/site-packages/IPython/core/ultratb.py\", line 1125, in structured_traceback\n",
      "    tb_offset)\n",
      "  File \"/home/bschroed/anaconda3/envs/pyGromosTools/lib/python3.7/site-packages/IPython/core/ultratb.py\", line 1082, in format_exception_as_a_whole\n",
      "    last_unique, recursion_repeat = find_recursion(orig_etype, evalue, records)\n",
      "  File \"/home/bschroed/anaconda3/envs/pyGromosTools/lib/python3.7/site-packages/IPython/core/ultratb.py\", line 382, in find_recursion\n",
      "    return len(records), 0\n",
      "TypeError: object of type 'NoneType' has no len()\n",
      "\n",
      "During handling of the above exception, another exception occurred:\n",
      "\n",
      "Traceback (most recent call last):\n",
      "  File \"/home/bschroed/anaconda3/envs/pyGromosTools/lib/python3.7/site-packages/IPython/core/interactiveshell.py\", line 2061, in showtraceback\n",
      "    stb = value._render_traceback_()\n",
      "AttributeError: 'TypeError' object has no attribute '_render_traceback_'\n",
      "\n",
      "During handling of the above exception, another exception occurred:\n",
      "\n",
      "Traceback (most recent call last):\n",
      "  File \"/home/bschroed/anaconda3/envs/pyGromosTools/lib/python3.7/site-packages/IPython/core/interactiveshell.py\", line 2944, in _run_cell\n",
      "    return runner(coro)\n",
      "  File \"/home/bschroed/anaconda3/envs/pyGromosTools/lib/python3.7/site-packages/IPython/core/async_helpers.py\", line 68, in _pseudo_sync_runner\n",
      "    coro.send(None)\n",
      "  File \"/home/bschroed/anaconda3/envs/pyGromosTools/lib/python3.7/site-packages/IPython/core/interactiveshell.py\", line 3170, in run_cell_async\n",
      "    interactivity=interactivity, compiler=compiler, result=result)\n",
      "  File \"/home/bschroed/anaconda3/envs/pyGromosTools/lib/python3.7/site-packages/IPython/core/interactiveshell.py\", line 3380, in run_ast_nodes\n",
      "    self.showtraceback()\n",
      "  File \"/home/bschroed/anaconda3/envs/pyGromosTools/lib/python3.7/site-packages/IPython/core/interactiveshell.py\", line 2064, in showtraceback\n",
      "    value, tb, tb_offset=tb_offset)\n",
      "  File \"/home/bschroed/anaconda3/envs/pyGromosTools/lib/python3.7/site-packages/IPython/core/ultratb.py\", line 1368, in structured_traceback\n",
      "    self, etype, value, tb, tb_offset, number_of_lines_of_context)\n",
      "  File \"/home/bschroed/anaconda3/envs/pyGromosTools/lib/python3.7/site-packages/IPython/core/ultratb.py\", line 1268, in structured_traceback\n",
      "    self, etype, value, tb, tb_offset, number_of_lines_of_context\n",
      "  File \"/home/bschroed/anaconda3/envs/pyGromosTools/lib/python3.7/site-packages/IPython/core/ultratb.py\", line 1143, in structured_traceback\n",
      "    chained_exceptions_tb_offset)\n",
      "  File \"/home/bschroed/anaconda3/envs/pyGromosTools/lib/python3.7/site-packages/IPython/core/ultratb.py\", line 1082, in format_exception_as_a_whole\n",
      "    last_unique, recursion_repeat = find_recursion(orig_etype, evalue, records)\n",
      "  File \"/home/bschroed/anaconda3/envs/pyGromosTools/lib/python3.7/site-packages/IPython/core/ultratb.py\", line 382, in find_recursion\n",
      "    return len(records), 0\n",
      "TypeError: object of type 'NoneType' has no len()\n",
      "\n",
      "During handling of the above exception, another exception occurred:\n",
      "\n",
      "Traceback (most recent call last):\n",
      "  File \"/home/bschroed/anaconda3/envs/pyGromosTools/lib/python3.7/site-packages/IPython/core/interactiveshell.py\", line 2061, in showtraceback\n",
      "    stb = value._render_traceback_()\n",
      "AttributeError: 'TypeError' object has no attribute '_render_traceback_'\n",
      "\n",
      "During handling of the above exception, another exception occurred:\n",
      "\n",
      "Traceback (most recent call last):\n",
      "  File \"/home/bschroed/anaconda3/envs/pyGromosTools/lib/python3.7/site-packages/IPython/core/ultratb.py\", line 1101, in get_records\n",
      "    return _fixed_getinnerframes(etb, number_of_lines_of_context, tb_offset)\n",
      "  File \"/home/bschroed/anaconda3/envs/pyGromosTools/lib/python3.7/site-packages/IPython/core/ultratb.py\", line 248, in wrapped\n",
      "    return f(*args, **kwargs)\n",
      "  File \"/home/bschroed/anaconda3/envs/pyGromosTools/lib/python3.7/site-packages/IPython/core/ultratb.py\", line 281, in _fixed_getinnerframes\n",
      "    records = fix_frame_records_filenames(inspect.getinnerframes(etb, context))\n",
      "  File \"/home/bschroed/anaconda3/envs/pyGromosTools/lib/python3.7/inspect.py\", line 1502, in getinnerframes\n",
      "    frameinfo = (tb.tb_frame,) + getframeinfo(tb, context)\n",
      "  File \"/home/bschroed/anaconda3/envs/pyGromosTools/lib/python3.7/inspect.py\", line 1460, in getframeinfo\n",
      "    filename = getsourcefile(frame) or getfile(frame)\n",
      "  File \"/home/bschroed/anaconda3/envs/pyGromosTools/lib/python3.7/inspect.py\", line 696, in getsourcefile\n",
      "    if getattr(getmodule(object, filename), '__loader__', None) is not None:\n",
      "  File \"/home/bschroed/anaconda3/envs/pyGromosTools/lib/python3.7/inspect.py\", line 725, in getmodule\n",
      "    file = getabsfile(object, _filename)\n",
      "  File \"/home/bschroed/anaconda3/envs/pyGromosTools/lib/python3.7/inspect.py\", line 709, in getabsfile\n",
      "    return os.path.normcase(os.path.abspath(_filename))\n",
      "  File \"/home/bschroed/anaconda3/envs/pyGromosTools/lib/python3.7/posixpath.py\", line 383, in abspath\n",
      "    cwd = os.getcwd()\n",
      "FileNotFoundError: [Errno 2] No such file or directory\n"
     ]
    }
   ],
   "source": [
    "import os\n",
    "import numpy as np\n",
    "from pygromos.files.gromos_system import Gromos_System\n",
    "from pygromos.simulations.hpc_queuing.submission_systems.local import LOCAL as subSystem\n",
    "\n",
    "from pygromos.utils import bash\n",
    "sys_name = \"M030_to_6KET\"\n",
    "root_dir = os.getcwd()+\"/example_files/TI_Calculation\"\n",
    "\n",
    "project_dir = bash.make_folder(root_dir+\"/\"+sys_name)\n",
    "sys_path = root_dir+\"/M030_to_6KET/b_vacuum_sd/sd_out_system.obj\"\n",
    "sd_gromos_system = Gromos_System.load(sys_path)\n",
    "\n",
    "sd_gromos_system.imd.WRITETRAJ.NTWG =  sd_gromos_system.imd.WRITETRAJ.NTWX = sd_gromos_system.imd.WRITETRAJ.NTWE =10\n",
    "sd_gromos_system.imd.STEP = 100\n",
    "\n",
    "sd_gromos_system"
   ]
  },
  {
   "cell_type": "markdown",
   "metadata": {},
   "source": [
    "## Submission"
   ]
  },
  {
   "cell_type": "code",
   "execution_count": null,
   "metadata": {
    "pycharm": {
     "name": "#%%\n"
    }
   },
   "outputs": [
    {
     "name": "stderr",
     "output_type": "stream",
     "text": [
      "ERROR:root:Internal Python error in the inspect module.\n",
      "Below is the traceback from this internal error.\n",
      "\n",
      "ERROR:root:Internal Python error in the inspect module.\n",
      "Below is the traceback from this internal error.\n",
      "\n"
     ]
    },
    {
     "name": "stdout",
     "output_type": "stream",
     "text": [
      "Traceback (most recent call last):\n",
      "  File \"/home/bschroed/anaconda3/envs/pyGromosTools/lib/python3.7/site-packages/IPython/core/interactiveshell.py\", line 3441, in run_code\n",
      "    exec(code_obj, self.user_global_ns, self.user_ns)\n",
      "  File \"<ipython-input-12-7457f4d28234>\", line 6, in <module>\n",
      "    TI_sampling(in_gromos_system = sd_gromos_system, project_dir=project_dir, step_name  = step_name,\n",
      "NameError: name 'sd_gromos_system' is not defined\n",
      "\n",
      "During handling of the above exception, another exception occurred:\n",
      "\n",
      "Traceback (most recent call last):\n",
      "  File \"/home/bschroed/anaconda3/envs/pyGromosTools/lib/python3.7/site-packages/IPython/core/interactiveshell.py\", line 2061, in showtraceback\n",
      "    stb = value._render_traceback_()\n",
      "AttributeError: 'NameError' object has no attribute '_render_traceback_'\n",
      "\n",
      "During handling of the above exception, another exception occurred:\n",
      "\n",
      "Traceback (most recent call last):\n",
      "  File \"/home/bschroed/anaconda3/envs/pyGromosTools/lib/python3.7/site-packages/IPython/core/ultratb.py\", line 1101, in get_records\n",
      "    return _fixed_getinnerframes(etb, number_of_lines_of_context, tb_offset)\n",
      "  File \"/home/bschroed/anaconda3/envs/pyGromosTools/lib/python3.7/site-packages/IPython/core/ultratb.py\", line 248, in wrapped\n",
      "    return f(*args, **kwargs)\n",
      "  File \"/home/bschroed/anaconda3/envs/pyGromosTools/lib/python3.7/site-packages/IPython/core/ultratb.py\", line 281, in _fixed_getinnerframes\n",
      "    records = fix_frame_records_filenames(inspect.getinnerframes(etb, context))\n",
      "ERROR! Session/line number was not unique in database. History logging moved to new session   File \"/home/bschroed/anaconda3/envs/pyGromosTools/lib/python3.7/inspect.py\", line 1502, in getinnerframes\n",
      "    frameinfo = (tb.tb_frame,) + getframeinfo(tb, context)\n",
      "  File \"/home/bschroed/anaconda3/envs/pyGromosTools/lib/python3.7/inspect.py\", line 1460, in getframeinfo\n",
      "    filename = getsourcefile(frame) or getfile(frame)\n",
      "174\n",
      "  File \"/home/bschroed/anaconda3/envs/pyGromosTools/lib/python3.7/inspect.py\", line 696, in getsourcefile\n",
      "    if getattr(getmodule(object, filename), '__loader__', None) is not None:\n",
      "  File \"/home/bschroed/anaconda3/envs/pyGromosTools/lib/python3.7/inspect.py\", line 725, in getmodule\n",
      "    file = getabsfile(object, _filename)\n",
      "  File \"/home/bschroed/anaconda3/envs/pyGromosTools/lib/python3.7/inspect.py\", line 709, in getabsfile\n",
      "    return os.path.normcase(os.path.abspath(_filename))\n",
      "  File \"/home/bschroed/anaconda3/envs/pyGromosTools/lib/python3.7/posixpath.py\", line 383, in abspath\n",
      "    cwd = os.getcwd()\n",
      "FileNotFoundError: [Errno 2] No such file or directory\n",
      "Traceback (most recent call last):\n",
      "  File \"/home/bschroed/anaconda3/envs/pyGromosTools/lib/python3.7/site-packages/IPython/core/interactiveshell.py\", line 3441, in run_code\n",
      "    exec(code_obj, self.user_global_ns, self.user_ns)\n",
      "  File \"<ipython-input-12-7457f4d28234>\", line 6, in <module>\n",
      "    TI_sampling(in_gromos_system = sd_gromos_system, project_dir=project_dir, step_name  = step_name,\n",
      "NameError: name 'sd_gromos_system' is not defined\n",
      "\n",
      "During handling of the above exception, another exception occurred:\n",
      "\n",
      "Traceback (most recent call last):\n",
      "  File \"/home/bschroed/anaconda3/envs/pyGromosTools/lib/python3.7/site-packages/IPython/core/interactiveshell.py\", line 2061, in showtraceback\n",
      "    stb = value._render_traceback_()\n",
      "AttributeError: 'NameError' object has no attribute '_render_traceback_'\n",
      "\n",
      "During handling of the above exception, another exception occurred:\n",
      "\n",
      "Traceback (most recent call last):\n",
      "  File \"/home/bschroed/anaconda3/envs/pyGromosTools/lib/python3.7/site-packages/IPython/core/interactiveshell.py\", line 3361, in run_ast_nodes\n",
      "    if (await self.run_code(code, result,  async_=asy)):\n",
      "  File \"/home/bschroed/anaconda3/envs/pyGromosTools/lib/python3.7/site-packages/IPython/core/interactiveshell.py\", line 3458, in run_code\n",
      "    self.showtraceback(running_compiled_code=True)\n",
      "  File \"/home/bschroed/anaconda3/envs/pyGromosTools/lib/python3.7/site-packages/IPython/core/interactiveshell.py\", line 2064, in showtraceback\n",
      "    value, tb, tb_offset=tb_offset)\n",
      "  File \"/home/bschroed/anaconda3/envs/pyGromosTools/lib/python3.7/site-packages/IPython/core/ultratb.py\", line 1368, in structured_traceback\n",
      "    self, etype, value, tb, tb_offset, number_of_lines_of_context)\n",
      "  File \"/home/bschroed/anaconda3/envs/pyGromosTools/lib/python3.7/site-packages/IPython/core/ultratb.py\", line 1268, in structured_traceback\n",
      "    self, etype, value, tb, tb_offset, number_of_lines_of_context\n",
      "  File \"/home/bschroed/anaconda3/envs/pyGromosTools/lib/python3.7/site-packages/IPython/core/ultratb.py\", line 1125, in structured_traceback\n",
      "    tb_offset)\n",
      "  File \"/home/bschroed/anaconda3/envs/pyGromosTools/lib/python3.7/site-packages/IPython/core/ultratb.py\", line 1082, in format_exception_as_a_whole\n",
      "    last_unique, recursion_repeat = find_recursion(orig_etype, evalue, records)\n",
      "  File \"/home/bschroed/anaconda3/envs/pyGromosTools/lib/python3.7/site-packages/IPython/core/ultratb.py\", line 382, in find_recursion\n",
      "    return len(records), 0\n",
      "TypeError: object of type 'NoneType' has no len()\n",
      "\n",
      "During handling of the above exception, another exception occurred:\n",
      "\n",
      "Traceback (most recent call last):\n",
      "  File \"/home/bschroed/anaconda3/envs/pyGromosTools/lib/python3.7/site-packages/IPython/core/interactiveshell.py\", line 2061, in showtraceback\n",
      "    stb = value._render_traceback_()\n",
      "AttributeError: 'TypeError' object has no attribute '_render_traceback_'\n",
      "\n",
      "During handling of the above exception, another exception occurred:\n",
      "\n",
      "Traceback (most recent call last):\n",
      "  File \"/home/bschroed/anaconda3/envs/pyGromosTools/lib/python3.7/site-packages/IPython/core/ultratb.py\", line 1101, in get_records\n",
      "    return _fixed_getinnerframes(etb, number_of_lines_of_context, tb_offset)\n",
      "  File \"/home/bschroed/anaconda3/envs/pyGromosTools/lib/python3.7/site-packages/IPython/core/ultratb.py\", line 248, in wrapped\n",
      "    return f(*args, **kwargs)\n",
      "  File \"/home/bschroed/anaconda3/envs/pyGromosTools/lib/python3.7/site-packages/IPython/core/ultratb.py\", line 281, in _fixed_getinnerframes\n",
      "    records = fix_frame_records_filenames(inspect.getinnerframes(etb, context))\n",
      "  File \"/home/bschroed/anaconda3/envs/pyGromosTools/lib/python3.7/inspect.py\", line 1502, in getinnerframes\n",
      "    frameinfo = (tb.tb_frame,) + getframeinfo(tb, context)\n",
      "  File \"/home/bschroed/anaconda3/envs/pyGromosTools/lib/python3.7/inspect.py\", line 1460, in getframeinfo\n",
      "    filename = getsourcefile(frame) or getfile(frame)\n",
      "  File \"/home/bschroed/anaconda3/envs/pyGromosTools/lib/python3.7/inspect.py\", line 696, in getsourcefile\n",
      "    if getattr(getmodule(object, filename), '__loader__', None) is not None:\n",
      "  File \"/home/bschroed/anaconda3/envs/pyGromosTools/lib/python3.7/inspect.py\", line 725, in getmodule\n",
      "    file = getabsfile(object, _filename)\n",
      "  File \"/home/bschroed/anaconda3/envs/pyGromosTools/lib/python3.7/inspect.py\", line 709, in getabsfile\n",
      "    return os.path.normcase(os.path.abspath(_filename))\n",
      "  File \"/home/bschroed/anaconda3/envs/pyGromosTools/lib/python3.7/posixpath.py\", line 383, in abspath\n",
      "    cwd = os.getcwd()\n",
      "FileNotFoundError: [Errno 2] No such file or directory\n"
     ]
    },
    {
     "name": "stderr",
     "output_type": "stream",
     "text": [
      "ERROR:root:Internal Python error in the inspect module.\n",
      "Below is the traceback from this internal error.\n",
      "\n"
     ]
    },
    {
     "name": "stdout",
     "output_type": "stream",
     "text": [
      "Traceback (most recent call last):\n",
      "  File \"/home/bschroed/anaconda3/envs/pyGromosTools/lib/python3.7/site-packages/IPython/core/interactiveshell.py\", line 3441, in run_code\n",
      "    exec(code_obj, self.user_global_ns, self.user_ns)\n",
      "  File \"<ipython-input-12-7457f4d28234>\", line 6, in <module>\n",
      "    TI_sampling(in_gromos_system = sd_gromos_system, project_dir=project_dir, step_name  = step_name,\n",
      "NameError: name 'sd_gromos_system' is not defined\n",
      "\n",
      "During handling of the above exception, another exception occurred:\n",
      "\n",
      "Traceback (most recent call last):\n",
      "  File \"/home/bschroed/anaconda3/envs/pyGromosTools/lib/python3.7/site-packages/IPython/core/interactiveshell.py\", line 2061, in showtraceback\n",
      "    stb = value._render_traceback_()\n",
      "AttributeError: 'NameError' object has no attribute '_render_traceback_'\n",
      "\n",
      "During handling of the above exception, another exception occurred:\n",
      "\n",
      "Traceback (most recent call last):\n",
      "  File \"/home/bschroed/anaconda3/envs/pyGromosTools/lib/python3.7/site-packages/IPython/core/interactiveshell.py\", line 3361, in run_ast_nodes\n",
      "    if (await self.run_code(code, result,  async_=asy)):\n",
      "  File \"/home/bschroed/anaconda3/envs/pyGromosTools/lib/python3.7/site-packages/IPython/core/interactiveshell.py\", line 3458, in run_code\n",
      "    self.showtraceback(running_compiled_code=True)\n",
      "  File \"/home/bschroed/anaconda3/envs/pyGromosTools/lib/python3.7/site-packages/IPython/core/interactiveshell.py\", line 2064, in showtraceback\n",
      "    value, tb, tb_offset=tb_offset)\n",
      "  File \"/home/bschroed/anaconda3/envs/pyGromosTools/lib/python3.7/site-packages/IPython/core/ultratb.py\", line 1368, in structured_traceback\n",
      "    self, etype, value, tb, tb_offset, number_of_lines_of_context)\n",
      "  File \"/home/bschroed/anaconda3/envs/pyGromosTools/lib/python3.7/site-packages/IPython/core/ultratb.py\", line 1268, in structured_traceback\n",
      "    self, etype, value, tb, tb_offset, number_of_lines_of_context\n",
      "  File \"/home/bschroed/anaconda3/envs/pyGromosTools/lib/python3.7/site-packages/IPython/core/ultratb.py\", line 1125, in structured_traceback\n",
      "    tb_offset)\n",
      "  File \"/home/bschroed/anaconda3/envs/pyGromosTools/lib/python3.7/site-packages/IPython/core/ultratb.py\", line 1082, in format_exception_as_a_whole\n",
      "    last_unique, recursion_repeat = find_recursion(orig_etype, evalue, records)\n",
      "  File \"/home/bschroed/anaconda3/envs/pyGromosTools/lib/python3.7/site-packages/IPython/core/ultratb.py\", line 382, in find_recursion\n",
      "    return len(records), 0\n",
      "TypeError: object of type 'NoneType' has no len()\n",
      "\n",
      "During handling of the above exception, another exception occurred:\n",
      "\n",
      "Traceback (most recent call last):\n",
      "  File \"/home/bschroed/anaconda3/envs/pyGromosTools/lib/python3.7/site-packages/IPython/core/interactiveshell.py\", line 2061, in showtraceback\n",
      "    stb = value._render_traceback_()\n",
      "AttributeError: 'TypeError' object has no attribute '_render_traceback_'\n",
      "\n",
      "During handling of the above exception, another exception occurred:\n",
      "\n",
      "Traceback (most recent call last):\n",
      "  File \"/home/bschroed/anaconda3/envs/pyGromosTools/lib/python3.7/site-packages/IPython/core/interactiveshell.py\", line 2944, in _run_cell\n",
      "    return runner(coro)\n",
      "  File \"/home/bschroed/anaconda3/envs/pyGromosTools/lib/python3.7/site-packages/IPython/core/async_helpers.py\", line 68, in _pseudo_sync_runner\n",
      "    coro.send(None)\n",
      "  File \"/home/bschroed/anaconda3/envs/pyGromosTools/lib/python3.7/site-packages/IPython/core/interactiveshell.py\", line 3170, in run_cell_async\n",
      "    interactivity=interactivity, compiler=compiler, result=result)\n",
      "  File \"/home/bschroed/anaconda3/envs/pyGromosTools/lib/python3.7/site-packages/IPython/core/interactiveshell.py\", line 3380, in run_ast_nodes\n",
      "    self.showtraceback()\n",
      "  File \"/home/bschroed/anaconda3/envs/pyGromosTools/lib/python3.7/site-packages/IPython/core/interactiveshell.py\", line 2064, in showtraceback\n",
      "    value, tb, tb_offset=tb_offset)\n",
      "  File \"/home/bschroed/anaconda3/envs/pyGromosTools/lib/python3.7/site-packages/IPython/core/ultratb.py\", line 1368, in structured_traceback\n",
      "    self, etype, value, tb, tb_offset, number_of_lines_of_context)\n",
      "  File \"/home/bschroed/anaconda3/envs/pyGromosTools/lib/python3.7/site-packages/IPython/core/ultratb.py\", line 1268, in structured_traceback\n",
      "    self, etype, value, tb, tb_offset, number_of_lines_of_context\n",
      "  File \"/home/bschroed/anaconda3/envs/pyGromosTools/lib/python3.7/site-packages/IPython/core/ultratb.py\", line 1143, in structured_traceback\n",
      "    chained_exceptions_tb_offset)\n",
      "  File \"/home/bschroed/anaconda3/envs/pyGromosTools/lib/python3.7/site-packages/IPython/core/ultratb.py\", line 1082, in format_exception_as_a_whole\n",
      "    last_unique, recursion_repeat = find_recursion(orig_etype, evalue, records)\n",
      "  File \"/home/bschroed/anaconda3/envs/pyGromosTools/lib/python3.7/site-packages/IPython/core/ultratb.py\", line 382, in find_recursion\n",
      "    return len(records), 0\n",
      "TypeError: object of type 'NoneType' has no len()\n",
      "\n",
      "During handling of the above exception, another exception occurred:\n",
      "\n",
      "Traceback (most recent call last):\n",
      "  File \"/home/bschroed/anaconda3/envs/pyGromosTools/lib/python3.7/site-packages/IPython/core/interactiveshell.py\", line 2061, in showtraceback\n",
      "    stb = value._render_traceback_()\n",
      "AttributeError: 'TypeError' object has no attribute '_render_traceback_'\n",
      "\n",
      "During handling of the above exception, another exception occurred:\n",
      "\n",
      "Traceback (most recent call last):\n",
      "  File \"/home/bschroed/anaconda3/envs/pyGromosTools/lib/python3.7/site-packages/IPython/core/ultratb.py\", line 1101, in get_records\n",
      "    return _fixed_getinnerframes(etb, number_of_lines_of_context, tb_offset)\n",
      "  File \"/home/bschroed/anaconda3/envs/pyGromosTools/lib/python3.7/site-packages/IPython/core/ultratb.py\", line 248, in wrapped\n",
      "    return f(*args, **kwargs)\n",
      "  File \"/home/bschroed/anaconda3/envs/pyGromosTools/lib/python3.7/site-packages/IPython/core/ultratb.py\", line 281, in _fixed_getinnerframes\n",
      "    records = fix_frame_records_filenames(inspect.getinnerframes(etb, context))\n",
      "  File \"/home/bschroed/anaconda3/envs/pyGromosTools/lib/python3.7/inspect.py\", line 1502, in getinnerframes\n",
      "    frameinfo = (tb.tb_frame,) + getframeinfo(tb, context)\n",
      "  File \"/home/bschroed/anaconda3/envs/pyGromosTools/lib/python3.7/inspect.py\", line 1460, in getframeinfo\n",
      "    filename = getsourcefile(frame) or getfile(frame)\n",
      "  File \"/home/bschroed/anaconda3/envs/pyGromosTools/lib/python3.7/inspect.py\", line 696, in getsourcefile\n",
      "    if getattr(getmodule(object, filename), '__loader__', None) is not None:\n",
      "  File \"/home/bschroed/anaconda3/envs/pyGromosTools/lib/python3.7/inspect.py\", line 725, in getmodule\n",
      "    file = getabsfile(object, _filename)\n",
      "  File \"/home/bschroed/anaconda3/envs/pyGromosTools/lib/python3.7/inspect.py\", line 709, in getabsfile\n",
      "    return os.path.normcase(os.path.abspath(_filename))\n",
      "  File \"/home/bschroed/anaconda3/envs/pyGromosTools/lib/python3.7/posixpath.py\", line 383, in abspath\n",
      "    cwd = os.getcwd()\n",
      "FileNotFoundError: [Errno 2] No such file or directory\n"
     ]
    }
   ],
   "source": [
    "from pygromos.simulations.modules.ti_modules import TI_sampling\n",
    "\n",
    "step_name  = \"d_lambda_sampling\"\n",
    "\n",
    "\n",
    "TI_sampling(in_gromos_system = sd_gromos_system, project_dir=project_dir, step_name  = step_name,\n",
    "            lambda_values= np.arange(0, 1.1, 0.1),\n",
    "            subSystem=subSystem(), n_simulation_repetitions = 3, n_equilibrations = 1)\n"
   ]
  },
  {
   "cell_type": "code",
   "execution_count": null,
   "metadata": {
    "pycharm": {
     "name": "#%%\n"
    }
   },
   "outputs": [],
   "source": []
  }
 ],
 "metadata": {
  "kernelspec": {
   "display_name": "Python 3 (ipykernel)",
   "language": "python",
   "name": "python3"
  },
  "language_info": {
   "codemirror_mode": {
    "name": "ipython",
    "version": 3
   },
   "file_extension": ".py",
   "mimetype": "text/x-python",
   "name": "python",
   "nbconvert_exporter": "python",
   "pygments_lexer": "ipython3",
   "version": "3.7.11"
  }
 },
 "nbformat": 4,
 "nbformat_minor": 4
}
